File: CuClQDs/XRD&XRF/20190611/A59_2thetaomega.ras
*RAS_DATA_START
*RAS_HEADER_START
*DISP_FMT_X "%.2f"
*DISP_FMT_Y "%.0f"
*DISP_FULLSCALE "779763.9296120625"
*DISP_LINE_COLOR "255.0000000000"
*DISP_LINE_STYLE "0.0000000000"
*DISP_LINE_WIDTH "0.2500000000"
*DISP_NOTE "測定データ-2"
*DISP_OFFSET_Y "0.0000000000"
*DISP_PEAKSEARCH_UNIT_Y "cps"
*DISP_RANGE_BOTTOM "0.0000000000"
*DISP_RANGE_LEFT "20.0000000000"
*DISP_RANGE_LOGCUTOFF "0.0100000000"
*DISP_RANGE_RIGHT "90.0000000000"
*DISP_RANGE_TOP "779763.9296120625"
*DISP_SCALE_MODE_Y "1.0000000000"
*DISP_TAB_NAME "2θ/ω"
*DISP_TITLE_Y "強度"
*DISP_UNIT_Y "cps"
*DISP_WINDOW_NAME "MSG_MACROENGINE"
*FILE_COMMENT " "
*FILE_MD5 ""
*FILE_MEMO " "
*FILE_OPERATOR "administrator"
*FILE_PART_ID "MEAS_KHP2_00061"
*FILE_SAMPLE "A59"
*FILE_TYPE "RAS_RAW"
*FILE_USERGROUP "システムマネージャ"
*FILE_VERSION "1.0000000000"
*HW_ATTACHMENT_ID "ATT0022"
*HW_ATTACHMENT_NAME "RxRy|RxRy"
*HW_COUNTER_ID-0 "CUT0021"
*HW_COUNTER_ID-1 "CUT0051"
*HW_COUNTER_ID-2 "CUT0020"
*HW_COUNTER_ID-3 "CSL0021"
*HW_COUNTER_ID-4 "CMC0021"
*HW_COUNTER_NAME-0 "SC-70|SC-70"
*HW_COUNTER_NAME-1 "HyPix 3000(H)|HyPix 3000(H)"
*HW_COUNTER_NAME-2 "None|None"
*HW_COUNTER_NAME-3 "BBM|BBM"
*HW_COUNTER_NAME-4 "検出器モノクロメータ|Detector monochromator"
*HW_COUNTER_SELECT_NAME "HyPix 3000(H)|HyPix 3000(H)"
*HW_GONIOMETER_ID "GON0024"
*HW_GONIOMETER_NAME "SmartLab(In-plane)|SmartLab(In-plane)"
*HW_GONIOMETER_RADIUS-0 "90.0"
*HW_GONIOMETER_RADIUS-1 "114.0"
*HW_GONIOMETER_RADIUS-2 "190.0"
*HW_GONIOMETER_RADIUS-3 "300.0"
*HW_GONIOMETER_RADIUS-4 "187.0"
*HW_GONIOMETER_RADIUS-5 "300.0"
*HW_GONIOMETER_RADIUS-6 "113.0"
*HW_GONIOMETER_RADIUS-7 "331.0"
*HW_I_OPT_ID-0 "CBO0021"
*HW_I_OPT_ID-1 "ICR0021"
*HW_I_OPT_ID-2 "ISL0021"
*HW_I_OPT_ID-3 "ISO0021"
*HW_I_OPT_ID-4 "IAD0021"
*HW_I_OPT_ID-5 "IPR0001"
*HW_I_OPT_NAME-0 "CBOユニット|CBO unit"
*HW_I_OPT_NAME-1 "標準入射光学ユニット|Standard incident optical unit"
*HW_I_OPT_NAME-2 "標準入射スリットボックス|Standard incident slit box"
*HW_I_OPT_NAME-3 "入射平行スリット|Incident parallel slit"
*HW_I_OPT_NAME-4 "長手制限スリット|Length limiting slit"
*HW_I_OPT_NAME-5 "None|None"
*HW_R_ATTENUATER_AUTOMODE "0"
*HW_R_OPT_ID-0 "RSS0022"
*HW_R_OPT_ID-1 "RCR0022"
*HW_R_OPT_ID-2 "RSO0021"
*HW_R_OPT_ID-3 "RRS0022"
*HW_R_OPT_ID-4 "ATN0020"
*HW_R_OPT_ID-5 "RFL0021"
*HW_R_OPT_ID-6 "RAD0021"
*HW_R_OPT_NAME-0 "受光スリットボックス1(Zr軸付)|Receiving slit box # 1 (w/ Zr Axis)"
*HW_R_OPT_NAME-1 "標準受光光学ユニット1|Standard receiving unit # 1"
*HW_R_OPT_NAME-2 "標準受光光学ユニット2|Standard receiving optical unit # 2"
*HW_R_OPT_NAME-3 "仮想受光スリット2|Virtual receiving slit #2"
*HW_R_OPT_NAME-4 "無し|None"
*HW_R_OPT_NAME-5 "Cu Kβ|Cu K-beta"
*HW_R_OPT_NAME-6 "調整用受光スリット|Alignment receiving slit"
*HW_SAMPLE_HOLDER_ID "SMP0021"
*HW_SAMPLE_HOLDER_NAME "χφZクレードル|Chi phi Z cradle"
*HW_XG_CURRENT_MAX "200"
*HW_XG_CURRENT_MIN "10"
*HW_XG_CURRENT_RESOLUTION "1"
*HW_XG_CURRENT_UNIT "mA"
*HW_XG_FOCUS "0.4mm x 8mm"
*HW_XG_FOCUS_TYPE "Normal"
*HW_XG_ID "1700"
*HW_XG_NAME "9kW 開放管(45kV 200mA ID:1700)|9kW Rotating anode(45kV 200mA ID:1700)"
*HW_XG_TARGET_ATOMIC_NUMBER "29.0000000000"
*HW_XG_TARGET_NAME "Cu"
*HW_XG_TYPE "Rota"
*HW_XG_VOLTAGE_MAX "45"
*HW_XG_VOLTAGE_MIN "20"
*HW_XG_VOLTAGE_RESOLUTION "1"
*HW_XG_VOLTAGE_UNIT "kV"
*HW_XG_WATT_MAX "9"
*HW_XG_WATT_UNIT "kW"
*HW_XG_WAVE_LENGTH_ALPHA1 "1.540593"
*HW_XG_WAVE_LENGTH_ALPHA2 "1.544414"
*HW_XG_WAVE_LENGTH_BETA "1.392250"
*MEAS_COND_AXIS_NAME-0 "2θ/θ"
*MEAS_COND_AXIS_NAME-1 "2θ"
*MEAS_COND_AXIS_NAME-2 "ω"
*MEAS_COND_AXIS_NAME-3 "χ"
*MEAS_COND_AXIS_NAME-4 "φ"
*MEAS_COND_AXIS_NAME-5 "Z"
*MEAS_COND_AXIS_NAME-6 "Rx"
*MEAS_COND_AXIS_NAME-7 "Ry"
*MEAS_COND_AXIS_NAME-8 "2θ/ω"
*MEAS_COND_AXIS_NAME-9 "2θχ"
*MEAS_COND_AXIS_NAME-10 "2θχ/φ"
*MEAS_COND_AXIS_NAME-11 "α"
*MEAS_COND_AXIS_NAME-12 "β"
*MEAS_COND_AXIS_NAME-13 "θs"
*MEAS_COND_AXIS_NAME-14 "θd"
*MEAS_COND_AXIS_NAME-15 "Ts"
*MEAS_COND_AXIS_NAME-16 "CBO選択スリット"
*MEAS_COND_AXIS_NAME-17 "M"
*MEAS_COND_AXIS_NAME-18 "入射平行スリット"
*MEAS_COND_AXIS_NAME-19 "入射スリット"
*MEAS_COND_AXIS_NAME-20 ""
*MEAS_COND_AXIS_NAME-21 "Zs"
*MEAS_COND_AXIS_NAME-22 "入射光学素子"
*MEAS_COND_AXIS_NAME-23 "ωm"
*MEAS_COND_AXIS_NAME-24 "長手制限スリット"
*MEAS_COND_AXIS_NAME-25 "センタースリット"
*MEAS_COND_AXIS_NAME-26 "フィルター"
*MEAS_COND_AXIS_NAME-27 "受光スリット1"
*MEAS_COND_AXIS_NAME-28 "受光スリット2"
*MEAS_COND_AXIS_NAME-29 "受光光学素子"
*MEAS_COND_AXIS_NAME-30 "受光平行スリット"
*MEAS_COND_AXIS_NAME-31 "調整用受光スリット"
*MEAS_COND_AXIS_NAME-32 ""
*MEAS_COND_AXIS_NAME-33 ""
*MEAS_COND_AXIS_NAME-34 "Zd"
*MEAS_COND_AXIS_NAME-35 "アッテネータ"
*MEAS_COND_AXIS_NAME-36 "検出器モノクロメータ"
*MEAS_COND_AXIS_NAME-37 "モノクロメータスリット"
*MEAS_COND_AXIS_NAME-38 "2θB"
*MEAS_COND_AXIS_NAME-39 ""
*MEAS_COND_AXIS_NAME-40 ""
*MEAS_COND_AXIS_NAME-41 "Zr"
*MEAS_COND_AXIS_NAME-42 "プライマリビーム"
*MEAS_COND_AXIS_NAME_INTERNAL-0 "TwoThetaTheta"
*MEAS_COND_AXIS_NAME_INTERNAL-1 "TwoTheta"
*MEAS_COND_AXIS_NAME_INTERNAL-2 "Omega"
*MEAS_COND_AXIS_NAME_INTERNAL-3 "Chi"
*MEAS_COND_AXIS_NAME_INTERNAL-4 "Phi"
*MEAS_COND_AXIS_NAME_INTERNAL-5 "Z"
*MEAS_COND_AXIS_NAME_INTERNAL-6 "Rx"
*MEAS_COND_AXIS_NAME_INTERNAL-7 "Ry"
*MEAS_COND_AXIS_NAME_INTERNAL-8 "TwoThetaOmega"
*MEAS_COND_AXIS_NAME_INTERNAL-9 "TwoThetaChi"
*MEAS_COND_AXIS_NAME_INTERNAL-10 "TwoThetaChiPhi"
*MEAS_COND_AXIS_NAME_INTERNAL-11 "Alpha"
*MEAS_COND_AXIS_NAME_INTERNAL-12 "Beta"
*MEAS_COND_AXIS_NAME_INTERNAL-13 "ThetaS"
*MEAS_COND_AXIS_NAME_INTERNAL-14 "ThetaD"
*MEAS_COND_AXIS_NAME_INTERNAL-15 "Ts"
*MEAS_COND_AXIS_NAME_INTERNAL-16 "CBO"
*MEAS_COND_AXIS_NAME_INTERNAL-17 "CBO-M"
*MEAS_COND_AXIS_NAME_INTERNAL-18 "IncidentSollerSlit"
*MEAS_COND_AXIS_NAME_INTERNAL-19 "IncidentSlitBox"
*MEAS_COND_AXIS_NAME_INTERNAL-20 "IncidentSlitBox-_Axis"
*MEAS_COND_AXIS_NAME_INTERNAL-21 "Zs"
*MEAS_COND_AXIS_NAME_INTERNAL-22 "IncidentMonochromator"
*MEAS_COND_AXIS_NAME_INTERNAL-23 "IncidentMonochromator-OmegaM"
*MEAS_COND_AXIS_NAME_INTERNAL-24 "IncidentAxdSlit"
*MEAS_COND_AXIS_NAME_INTERNAL-25 "CenterSlit"
*MEAS_COND_AXIS_NAME_INTERNAL-26 "Filter"
*MEAS_COND_AXIS_NAME_INTERNAL-27 "ReceivingSlitBox1"
*MEAS_COND_AXIS_NAME_INTERNAL-28 "ReceivingSlitBox2"
*MEAS_COND_AXIS_NAME_INTERNAL-29 "ReceivingOptics"
*MEAS_COND_AXIS_NAME_INTERNAL-30 "ReceivingSollerSlit"
*MEAS_COND_AXIS_NAME_INTERNAL-31 "ReceivingAxdSlit"
*MEAS_COND_AXIS_NAME_INTERNAL-32 "ReceivingSlitBox1-_Axis"
*MEAS_COND_AXIS_NAME_INTERNAL-33 "ReceivingSlitBox2-_Axis"
*MEAS_COND_AXIS_NAME_INTERNAL-34 "ReceivingSlitBox2-Zd"
*MEAS_COND_AXIS_NAME_INTERNAL-35 "Attenuator"
*MEAS_COND_AXIS_NAME_INTERNAL-36 "CounterMonochromator"
*MEAS_COND_AXIS_NAME_INTERNAL-37 "CounterSlit"
*MEAS_COND_AXIS_NAME_INTERNAL-38 "TwoThetaB"
*MEAS_COND_AXIS_NAME_INTERNAL-39 "AlphaR"
*MEAS_COND_AXIS_NAME_INTERNAL-40 "BetaR"
*MEAS_COND_AXIS_NAME_INTERNAL-41 "ReceivingSlitBox1-Zr"
*MEAS_COND_AXIS_NAME_INTERNAL-42 "IncidentPrimary"
*MEAS_COND_AXIS_NAME_MAGICNO-0 "83951616.0000000000"
*MEAS_COND_AXIS_NAME_MAGICNO-1 "268632064.0000000000"
*MEAS_COND_AXIS_NAME_MAGICNO-2 "268500992.0000000000"
*MEAS_COND_AXIS_NAME_MAGICNO-3 "268500992.0000000000"
*MEAS_COND_AXIS_NAME_MAGICNO-4 "268500992.0000000000"
*MEAS_COND_AXIS_NAME_MAGICNO-5 "285278208.0000000000"
*MEAS_COND_AXIS_NAME_MAGICNO-6 "285278208.0000000000"
*MEAS_COND_AXIS_NAME_MAGICNO-7 "285278208.0000000000"
*MEAS_COND_AXIS_NAME_MAGICNO-8 "83951616.0000000000"
*MEAS_COND_AXIS_NAME_MAGICNO-9 "268632064.0000000000"
*MEAS_COND_AXIS_NAME_MAGICNO-10 "83951616.0000000000"
*MEAS_COND_AXIS_NAME_MAGICNO-11 "17039360.0000000000"
*MEAS_COND_AXIS_NAME_MAGICNO-12 "17039360.0000000000"
*MEAS_COND_AXIS_NAME_MAGICNO-13 "131072.0000000000"
*MEAS_COND_AXIS_NAME_MAGICNO-14 "131072.0000000000"
*MEAS_COND_AXIS_NAME_MAGICNO-15 "318898176.0000000000"
*MEAS_COND_AXIS_NAME_MAGICNO-16 "20971521.0000000000"
*MEAS_COND_AXIS_NAME_MAGICNO-17 "285343744.0000000000"
*MEAS_COND_AXIS_NAME_MAGICNO-18 "20971521.0000000000"
*MEAS_COND_AXIS_NAME_MAGICNO-19 "22020097.0000000000"
*MEAS_COND_AXIS_NAME_MAGICNO-20 "25165824.0000000000"
*MEAS_COND_AXIS_NAME_MAGICNO-21 "318898176.0000000000"
*MEAS_COND_AXIS_NAME_MAGICNO-22 "20971521.0000000000"
*MEAS_COND_AXIS_NAME_MAGICNO-23 "285343744.0000000000"
*MEAS_COND_AXIS_NAME_MAGICNO-24 "20971521.0000000000"
*MEAS_COND_AXIS_NAME_MAGICNO-25 "20971521.0000000000"
*MEAS_COND_AXIS_NAME_MAGICNO-26 "20971521.0000000000"
*MEAS_COND_AXIS_NAME_MAGICNO-27 "23068673.0000000000"
*MEAS_COND_AXIS_NAME_MAGICNO-28 "23068673.0000000000"
*MEAS_COND_AXIS_NAME_MAGICNO-29 "20971521.0000000000"
*MEAS_COND_AXIS_NAME_MAGICNO-30 "20971521.0000000000"
*MEAS_COND_AXIS_NAME_MAGICNO-31 "20971521.0000000000"
*MEAS_COND_AXIS_NAME_MAGICNO-32 "25165824.0000000000"
*MEAS_COND_AXIS_NAME_MAGICNO-33 "25165824.0000000000"
*MEAS_COND_AXIS_NAME_MAGICNO-34 "285343744.0000000000"
*MEAS_COND_AXIS_NAME_MAGICNO-35 "0.0000000000"
*MEAS_COND_AXIS_NAME_MAGICNO-36 "20971521.0000000000"
*MEAS_COND_AXIS_NAME_MAGICNO-37 "20971521.0000000000"
*MEAS_COND_AXIS_NAME_MAGICNO-38 "17039360.0000000000"
*MEAS_COND_AXIS_NAME_MAGICNO-39 "8388608.0000000000"
*MEAS_COND_AXIS_NAME_MAGICNO-40 "8388608.0000000000"
*MEAS_COND_AXIS_NAME_MAGICNO-41 "285343744.0000000000"
*MEAS_COND_AXIS_NAME_MAGICNO-42 "20971521.0000000000"
*MEAS_COND_AXIS_OFFSET-0 "-"
*MEAS_COND_AXIS_OFFSET-1 "0.8399000000"
*MEAS_COND_AXIS_OFFSET-2 "0.6789000000"
*MEAS_COND_AXIS_OFFSET-3 "0.0000000000"
*MEAS_COND_AXIS_OFFSET-4 "0.0000000000"
*MEAS_COND_AXIS_OFFSET-5 "-"
*MEAS_COND_AXIS_OFFSET-6 "-"
*MEAS_COND_AXIS_OFFSET-7 "-"
*MEAS_COND_AXIS_OFFSET-8 "-"
*MEAS_COND_AXIS_OFFSET-9 "0.0000000000"
*MEAS_COND_AXIS_OFFSET-10 "-"
*MEAS_COND_AXIS_OFFSET-11 "-"
*MEAS_COND_AXIS_OFFSET-12 "-"
*MEAS_COND_AXIS_OFFSET-13 "0.6789000000"
*MEAS_COND_AXIS_OFFSET-14 "0.1610000000"
*MEAS_COND_AXIS_OFFSET-15 "-"
*MEAS_COND_AXIS_OFFSET-16 "-"
*MEAS_COND_AXIS_OFFSET-17 "-"
*MEAS_COND_AXIS_OFFSET-18 "-"
*MEAS_COND_AXIS_OFFSET-19 "-"
*MEAS_COND_AXIS_OFFSET-20 "-"
*MEAS_COND_AXIS_OFFSET-21 "-"
*MEAS_COND_AXIS_OFFSET-22 "-"
*MEAS_COND_AXIS_OFFSET-23 "-"
*MEAS_COND_AXIS_OFFSET-24 "-"
*MEAS_COND_AXIS_OFFSET-25 "-"
*MEAS_COND_AXIS_OFFSET-26 "-"
*MEAS_COND_AXIS_OFFSET-27 "-"
*MEAS_COND_AXIS_OFFSET-28 "-"
*MEAS_COND_AXIS_OFFSET-29 "-"
*MEAS_COND_AXIS_OFFSET-30 "-"
*MEAS_COND_AXIS_OFFSET-31 "-"
*MEAS_COND_AXIS_OFFSET-32 "-"
*MEAS_COND_AXIS_OFFSET-33 "-"
*MEAS_COND_AXIS_OFFSET-34 "-"
*MEAS_COND_AXIS_OFFSET-35 "-"
*MEAS_COND_AXIS_OFFSET-36 "-"
*MEAS_COND_AXIS_OFFSET-37 "-"
*MEAS_COND_AXIS_OFFSET-38 "-"
*MEAS_COND_AXIS_OFFSET-39 "0.0000000000"
*MEAS_COND_AXIS_OFFSET-40 "0.0000000000"
*MEAS_COND_AXIS_OFFSET-41 "-"
*MEAS_COND_AXIS_OFFSET-42 "-"
*MEAS_COND_AXIS_POSITION-0 "20.0000000000"
*MEAS_COND_AXIS_POSITION-1 "20.0000000000"
*MEAS_COND_AXIS_POSITION-2 "10.0000000000"
*MEAS_COND_AXIS_POSITION-3 "0.0000000000"
*MEAS_COND_AXIS_POSITION-4 "0.0000000000"
*MEAS_COND_AXIS_POSITION-5 "-0.5135000000"
*MEAS_COND_AXIS_POSITION-6 "0.0000000000"
*MEAS_COND_AXIS_POSITION-7 "0.0000000000"
*MEAS_COND_AXIS_POSITION-8 "20.0000000000"
*MEAS_COND_AXIS_POSITION-9 "0.0000000000"
*MEAS_COND_AXIS_POSITION-10 "0.0000000000"
*MEAS_COND_AXIS_POSITION-11 "90.0000000000"
*MEAS_COND_AXIS_POSITION-12 "0.0000000000"
*MEAS_COND_AXIS_POSITION-13 "10.0000000000"
*MEAS_COND_AXIS_POSITION-14 "10.0000000000"
*MEAS_COND_AXIS_POSITION-15 "-5.8458800000"
*MEAS_COND_AXIS_POSITION-16 "PB"
*MEAS_COND_AXIS_POSITION-17 "0.0000000000"
*MEAS_COND_AXIS_POSITION-18 "Soller_slit_open_s"
*MEAS_COND_AXIS_POSITION-19 "0.500mm"
*MEAS_COND_AXIS_POSITION-20 "0.5000000000"
*MEAS_COND_AXIS_POSITION-21 "-1.6046900000"
*MEAS_COND_AXIS_POSITION-22 "Ge(220)x2"
*MEAS_COND_AXIS_POSITION-23 "0.0000000000"
*MEAS_COND_AXIS_POSITION-24 "2.0mm"
*MEAS_COND_AXIS_POSITION-25 "None"
*MEAS_COND_AXIS_POSITION-26 "None"
*MEAS_COND_AXIS_POSITION-27 "0.500mm"
*MEAS_COND_AXIS_POSITION-28 "0.500mm"
*MEAS_COND_AXIS_POSITION-29 "PSA_open"
*MEAS_COND_AXIS_POSITION-30 "Soller_slit_5.0deg"
*MEAS_COND_AXIS_POSITION-31 "None"
*MEAS_COND_AXIS_POSITION-32 "0.5000000000"
*MEAS_COND_AXIS_POSITION-33 "0.5000000000"
*MEAS_COND_AXIS_POSITION-34 "0.0000000000"
*MEAS_COND_AXIS_POSITION-35 "-"
*MEAS_COND_AXIS_POSITION-36 "No_unit"
*MEAS_COND_AXIS_POSITION-37 "None"
*MEAS_COND_AXIS_POSITION-38 "20.0000000000"
*MEAS_COND_AXIS_POSITION-39 "0.0000000000"
*MEAS_COND_AXIS_POSITION-40 "0.0000000000"
*MEAS_COND_AXIS_POSITION-41 "-0.3831200000"
*MEAS_COND_AXIS_POSITION-42 "None"
*MEAS_COND_AXIS_UNIT-0 "deg"
*MEAS_COND_AXIS_UNIT-1 "deg"
*MEAS_COND_AXIS_UNIT-2 "deg"
*MEAS_COND_AXIS_UNIT-3 "deg"
*MEAS_COND_AXIS_UNIT-4 "deg"
*MEAS_COND_AXIS_UNIT-5 "mm"
*MEAS_COND_AXIS_UNIT-6 "deg"
*MEAS_COND_AXIS_UNIT-7 "deg"
*MEAS_COND_AXIS_UNIT-8 "deg"
*MEAS_COND_AXIS_UNIT-9 "deg"
*MEAS_COND_AXIS_UNIT-10 "deg"
*MEAS_COND_AXIS_UNIT-11 "deg"
*MEAS_COND_AXIS_UNIT-12 "deg"
*MEAS_COND_AXIS_UNIT-13 "deg"
*MEAS_COND_AXIS_UNIT-14 "deg"
*MEAS_COND_AXIS_UNIT-15 "mm"
*MEAS_COND_AXIS_UNIT-16 ""
*MEAS_COND_AXIS_UNIT-17 "pulse"
*MEAS_COND_AXIS_UNIT-18 ""
*MEAS_COND_AXIS_UNIT-19 ""
*MEAS_COND_AXIS_UNIT-20 "mm"
*MEAS_COND_AXIS_UNIT-21 "mm"
*MEAS_COND_AXIS_UNIT-22 ""
*MEAS_COND_AXIS_UNIT-23 "pulse"
*MEAS_COND_AXIS_UNIT-24 ""
*MEAS_COND_AXIS_UNIT-25 ""
*MEAS_COND_AXIS_UNIT-26 ""
*MEAS_COND_AXIS_UNIT-27 ""
*MEAS_COND_AXIS_UNIT-28 ""
*MEAS_COND_AXIS_UNIT-29 ""
*MEAS_COND_AXIS_UNIT-30 ""
*MEAS_COND_AXIS_UNIT-31 ""
*MEAS_COND_AXIS_UNIT-32 "mm"
*MEAS_COND_AXIS_UNIT-33 "mm"
*MEAS_COND_AXIS_UNIT-34 "mm"
*MEAS_COND_AXIS_UNIT-35 ""
*MEAS_COND_AXIS_UNIT-36 ""
*MEAS_COND_AXIS_UNIT-37 ""
*MEAS_COND_AXIS_UNIT-38 "deg"
*MEAS_COND_AXIS_UNIT-39 "deg"
*MEAS_COND_AXIS_UNIT-40 "deg"
*MEAS_COND_AXIS_UNIT-41 "mm"
*MEAS_COND_AXIS_UNIT-42 ""
*MEAS_COND_COUNTER_CNTLOSS_CORR "0.0000000000"
*MEAS_COND_COUNTER_TAUDIFF "0.0000000000"
*MEAS_COND_COUNTER_TAUINT "0.0000000000"
*MEAS_COND_COUNTER_TEMP_CONDITION "NORMAL"
*MEAS_COND_IRRADIATION_MODE "OFF"
*MEAS_COND_IRRADIATION_WIDTH ""
*MEAS_COND_OPT_ATTR "高分解能平行ビームGe(220)x2/受光スリット"
*MEAS_COND_OPT_NAME "@高分解能PB-Ge(220)x2"
*MEAS_COND_UNSYMMETRIC_MODE "OFF"
*MEAS_COND_XG_CURRENT "200.0000000000"
*MEAS_COND_XG_VOLTAGE "45.0000000000"
*MEAS_COND_XG_WAVE_TYPE "Ka1"
*MEAS_DATA_COUNT "7001.0000000000"
*MEAS_SCAN_AXIS_X "2θ/ω"
*MEAS_SCAN_AXIS_X_INTERNAL "TwoThetaOmega"
*MEAS_SCAN_END_TIME "06/11/19 11:40:25"
*MEAS_SCAN_MODE "CONTINUOUS"
*MEAS_SCAN_MONITOR "0"
*MEAS_SCAN_RESOLUTION_X "0.0002"
*MEAS_SCAN_SPEED "5.158557"
*MEAS_SCAN_SPEED_UNIT "deg/min"
*MEAS_SCAN_SPEED_USER "5.000000"
*MEAS_SCAN_START "20.0000000000"
*MEAS_SCAN_START_TIME "06/11/19 11:26:12"
*MEAS_SCAN_STEP "0.0100000000"
*MEAS_SCAN_STOP "90.0000000000"
*MEAS_SCAN_UNIT_X "deg"
*MEAS_SCAN_UNIT_Y "counts"
*RAS_HEADER_END
*RAS_INT_START
20.0000 0.9849 1.0000
20.0500 1.0085 1.0000
20.1000 0.0000 1.0000
20.1500 0.0000 1.0000
20.2000 1.9852 1.0000
20.2500 0.0000 1.0000
20.3000 0.0000 1.0000
20.3500 0.9883 1.0000
20.4000 0.0000 1.0000
20.4500 0.0000 1.0000
20.5000 3.9704 1.0000
20.5500 0.9890 1.0000
20.6000 1.9986 1.0000
20.6500 0.0000 1.0000
20.7000 1.9828 1.0000
20.7500 1.9967 1.0000
20.8000 2.9785 1.0000
20.8500 1.9580 1.0000
20.9000 1.9797 1.0000
20.9500 0.0000 1.0000
21.0000 1.0121 1.0000
21.0500 2.9942 1.0000
21.1000 1.0002 1.0000
21.1500 3.9792 1.0000
21.2000 0.9880 1.0000
21.2500 3.9915 1.0000
21.3000 0.0000 1.0000
21.3500 0.9920 1.0000
21.4000 3.0135 1.0000
21.4500 0.9899 1.0000
21.5000 0.0000 1.0000
21.5500 0.9926 1.0000
21.6000 1.9895 1.0000
21.6500 0.0000 1.0000
21.7000 0.0000 1.0000
21.7500 0.9840 1.0000
21.8000 0.0000 1.0000
21.8500 1.0019 1.0000
21.9000 1.9940 1.0000
21.9500 0.0000 1.0000
22.0000 1.9772 1.0000
22.0500 0.9948 1.0000
22.1000 1.9726 1.0000
22.1500 3.0115 1.0000
22.2000 3.0114 1.0000
22.2500 2.0197 1.0000
22.3000 0.9701 1.0000
22.3500 1.9812 1.0000
22.4000 1.9643 1.0000
22.4500 1.9731 1.0000
22.5000 0.0000 1.0000
22.5500 0.9883 1.0000
22.6000 1.9871 1.0000
22.6500 0.9989 1.0000
22.7000 1.0038 1.0000
22.7500 2.0164 1.0000
22.8000 2.9867 1.0000
22.8500 1.0061 1.0000
22.9000 3.0215 1.0000
22.9500 1.9554 1.0000
23.0000 1.0122 1.0000
23.0500 1.0338 1.0000
23.1000 2.0097 1.0000
23.1500 2.1367 1.0000
23.2000 1.0020 1.0000
23.2500 0.9826 1.0000
23.3000 6.9897 1.0000
23.3500 0.0000 1.0000
23.4000 0.0000 1.0000
23.4500 0.9942 1.0000
23.5000 6.0470 1.0000
23.5500 0.9919 1.0000
23.6000 0.0000 1.0000
23.6500 3.0036 1.0000
23.7000 1.9865 1.0000
23.7500 3.9889 1.0000
23.8000 2.9788 1.0000
23.8500 0.0000 1.0000
23.9000 0.0000 1.0000
23.9500 1.9826 1.0000
24.0000 0.0000 1.0000
24.0500 1.9846 1.0000
24.1000 1.0194 1.0000
24.1500 2.9667 1.0000
24.2000 0.0000 1.0000
24.2500 0.9990 1.0000
24.3000 1.9693 1.0000
24.3500 2.9841 1.0000
24.4000 1.9860 1.0000
24.4500 1.9842 1.0000
24.5000 1.9906 1.0000
24.5500 0.9942 1.0000
24.6000 0.0000 1.0000
24.6500 1.9827 1.0000
24.7000 1.9844 1.0000
24.7500 0.0000 1.0000
24.8000 0.9609 1.0000
24.8500 0.0000 1.0000
24.9000 3.0228 1.0000
24.9500 4.0031 1.0000
25.0000 1.9400 1.0000
25.0500 0.9932 1.0000
25.1000 0.9941 1.0000
25.1500 0.9979 1.0000
25.2000 0.0000 1.0000
25.2500 1.0009 1.0000
25.3000 0.9831 1.0000
25.3500 0.0000 1.0000
25.4000 2.0029 1.0000
25.4500 2.9695 1.0000
25.5000 1.9687 1.0000
25.5500 3.9717 1.0000
25.6000 0.0000 1.0000
25.6500 3.9951 1.0000
25.7000 0.0000 1.0000
25.7500 0.9977 1.0000
25.8000 2.0019 1.0000
25.8500 2.9748 1.0000
25.9000 0.9530 1.0000
25.9500 1.9837 1.0000
26.0000 0.0000 1.0000
26.0500 1.9986 1.0000
26.1000 0.0000 1.0000
26.1500 3.9364 1.0000
26.2000 1.9887 1.0000
26.2500 0.0000 1.0000
26.3000 0.0000 1.0000
26.3500 0.9939 1.0000
26.4000 0.9983 1.0000
26.4500 2.0120 1.0000
26.5000 2.9612 1.0000
26.5500 0.9912 1.0000
26.6000 0.9989 1.0000
26.6500 2.0822 1.0000
26.7000 1.9915 1.0000
26.7500 2.9594 1.0000
26.8000 1.0053 1.0000
26.8500 1.9961 1.0000
26.9000 0.9975 1.0000
26.9500 1.9586 1.0000
27.0000 3.0310 1.0000
27.0500 1.9862 1.0000
27.1000 1.9746 1.0000
27.1500 0.0000 1.0000
27.2000 1.9877 1.0000
27.2500 0.0000 1.0000
27.3000 4.9690 1.0000
27.3500 0.0000 1.0000
27.4000 2.9697 1.0000
27.4500 0.0000 1.0000
27.5000 0.9971 1.0000
27.5500 0.0000 1.0000
27.6000 1.9922 1.0000
27.6500 2.9693 1.0000
27.7000 5.9648 1.0000
27.7500 1.9877 1.0000
27.8000 0.9991 1.0000
27.8500 2.0238 1.0000
27.9000 1.9685 1.0000
27.9500 0.9893 1.0000
28.0000 1.9876 1.0000
28.0500 2.9681 1.0000
28.1000 3.0280 1.0000
28.1500 2.0020 1.0000
28.2000 1.9520 1.0000
28.2500 5.9630 1.0000
28.3000 1.0014 1.0000
28.3500 2.0028 1.0000
28.4000 4.0189 1.0000
28.4500 1.9895 1.0000
28.5000 1.0199 1.0000
28.5500 3.9893 1.0000
28.6000 1.0250 1.0000
28.6500 0.9932 1.0000
28.7000 1.0110 1.0000
28.7500 0.9983 1.0000
28.8000 0.0000 1.0000
28.8500 0.9948 1.0000
28.9000 0.0000 1.0000
28.9500 2.0400 1.0000
29.0000 1.0059 1.0000
29.0500 3.0084 1.0000
29.1000 1.9675 1.0000
29.1500 3.0262 1.0000
29.2000 0.0000 1.0000
29.2500 0.0000 1.0000
29.3000 0.9701 1.0000
29.3500 2.0132 1.0000
29.4000 3.9994 1.0000
29.4500 0.9983 1.0000
29.5000 4.0088 1.0000
29.5500 0.9918 1.0000
29.6000 2.0294 1.0000
29.6500 3.9749 1.0000
29.7000 3.0204 1.0000
29.7500 1.9929 1.0000
29.8000 2.9759 1.0000
29.8500 3.9967 1.0000
29.9000 5.9411 1.0000
29.9500 3.9458 1.0000
30.0000 3.9590 1.0000
30.0500 1.9955 1.0000
30.1000 3.9571 1.0000
30.1500 5.9836 1.0000
30.2000 2.0001 1.0000
30.2500 1.9907 1.0000
30.3000 2.0285 1.0000
30.3500 0.9829 1.0000
30.4000 1.9875 1.0000
30.4500 4.9960 1.0000
30.5000 8.0030 1.0000
30.5500 7.0437 1.0000
30.6000 6.9612 1.0000
30.6500 7.2418 1.0000
30.7000 10.9557 1.0000
30.7500 6.9674 1.0000
30.8000 11.2872 1.0000
30.8500 20.1351 1.0000
30.9000 8.9690 1.0000
30.9500 20.2729 1.0000
31.0000 18.9709 1.0000
31.0500 18.8966 1.0000
31.1000 16.1685 1.0000
31.1500 24.0197 1.0000
31.2000 27.7579 1.0000
31.2500 45.0474 1.0000
31.3000 34.9033 1.0000
31.3500 42.0549 1.0000
31.4000 54.2075 1.0000
31.4500 72.1651 1.0000
31.5000 103.6201 1.0000
31.5500 191.7548 1.0000
31.6000 533.2079 1.0000
31.6500 4068.0823 1.0000
31.7000 71919.4297 1.0000
31.7500 49898.5430 1.0000
31.8000 6904.6357 1.0000
31.8500 210.6049 1.0000
31.9000 78.7648 1.0000
31.9500 42.1983 1.0000
32.0000 19.8203 1.0000
32.0500 20.1929 1.0000
32.1000 16.9121 1.0000
32.1500 5.9702 1.0000
32.2000 12.9557 1.0000
32.2500 11.1514 1.0000
32.3000 11.9321 1.0000
32.3500 7.0374 1.0000
32.4000 10.9669 1.0000
32.4500 3.0054 1.0000
32.5000 9.0757 1.0000
32.5500 3.9682 1.0000
32.6000 8.9499 1.0000
32.6500 4.0278 1.0000
32.7000 3.9764 1.0000
32.7500 9.9529 1.0000
32.8000 2.9947 1.0000
32.8500 2.9767 1.0000
32.9000 3.9723 1.0000
32.9500 5.9836 1.0000
33.0000 4.9683 1.0000
33.0500 4.2971 1.0000
33.1000 4.9232 1.0000
33.1500 2.9960 1.0000
33.2000 4.9514 1.0000
33.2500 0.9930 1.0000
33.3000 1.0039 1.0000
33.3500 2.9577 1.0000
33.4000 2.0170 1.0000
33.4500 5.9975 1.0000
33.5000 2.9775 1.0000
33.5500 2.9928 1.0000
33.6000 5.9551 1.0000
33.6500 2.9582 1.0000
33.7000 1.9665 1.0000
33.7500 6.9489 1.0000
33.8000 0.9930 1.0000
33.8500 1.0011 1.0000
33.9000 0.0000 1.0000
33.9500 1.9539 1.0000
34.0000 4.0350 1.0000
34.0500 3.0079 1.0000
34.1000 2.9736 1.0000
34.1500 3.9369 1.0000
34.2000 1.0029 1.0000
34.2500 5.9401 1.0000
34.3000 0.9989 1.0000
34.3500 2.9755 1.0000
34.4000 2.9983 1.0000
34.4500 0.9932 1.0000
34.5000 3.9508 1.0000
34.5500 1.9621 1.0000
34.6000 2.9733 1.0000
34.6500 1.9797 1.0000
34.7000 1.9782 1.0000
34.7500 3.0574 1.0000
34.8000 3.9898 1.0000
34.8500 0.0000 1.0000
34.9000 0.9964 1.0000
34.9500 3.0169 1.0000
35.0000 0.9530 1.0000
35.0500 2.9835 1.0000
35.1000 2.0167 1.0000
35.1500 1.9511 1.0000
35.2000 0.9710 1.0000
35.2500 3.0158 1.0000
35.3000 1.9830 1.0000
35.3500 0.9965 1.0000
35.4000 0.0000 1.0000
35.4500 1.9613 1.0000
35.5000 0.0000 1.0000
35.5500 1.0296 1.0000
35.6000 2.0153 1.0000
35.6500 2.0254 1.0000
35.7000 3.9761 1.0000
35.7500 2.9614 1.0000
35.8000 2.9986 1.0000
35.8500 2.9796 1.0000
35.9000 2.9496 1.0000
35.9500 0.9984 1.0000
36.0000 1.0092 1.0000
36.0500 0.9886 1.0000
36.1000 0.0000 1.0000
36.1500 1.0066 1.0000
36.2000 2.0006 1.0000
36.2500 0.0000 1.0000
36.3000 1.9591 1.0000
36.3500 2.9485 1.0000
36.4000 0.9746 1.0000
36.4500 0.9955 1.0000
36.5000 1.9920 1.0000
36.5500 2.9787 1.0000
36.6000 1.0121 1.0000
36.6500 0.0000 1.0000
36.7000 0.9955 1.0000
36.7500 1.0045 1.0000
36.8000 1.9769 1.0000
36.8500 0.0000 1.0000
36.9000 0.9934 1.0000
36.9500 2.9720 1.0000
37.0000 1.9854 1.0000
37.0500 0.9975 1.0000
37.1000 2.9766 1.0000
37.1500 0.0000 1.0000
37.2000 0.9755 1.0000
37.2500 0.9755 1.0000
37.3000 0.9716 1.0000
37.3500 4.9502 1.0000
37.4000 0.9918 1.0000
37.4500 0.9996 1.0000
37.5000 3.0485 1.0000
37.5500 1.9934 1.0000
37.6000 3.0058 1.0000
37.6500 2.9866 1.0000
37.7000 0.0000 1.0000
37.7500 2.9662 1.0000
37.8000 3.9537 1.0000
37.8500 3.9963 1.0000
37.9000 2.0060 1.0000
37.9500 2.9586 1.0000
38.0000 3.0121 1.0000
38.0500 2.9735 1.0000
38.1000 2.9877 1.0000
38.1500 0.0000 1.0000
38.2000 1.9958 1.0000
38.2500 2.0025 1.0000
38.3000 0.9920 1.0000
38.3500 4.9953 1.0000
38.4000 1.9771 1.0000
38.4500 1.9681 1.0000
38.5000 2.0210 1.0000
38.5500 1.0190 1.0000
38.6000 1.0116 1.0000
38.6500 4.0023 1.0000
38.7000 1.9776 1.0000
38.7500 1.9876 1.0000
38.8000 0.9829 1.0000
38.8500 0.9994 1.0000
38.9000 1.9865 1.0000
38.9500 1.9697 1.0000
39.0000 0.0000 1.0000
39.0500 0.0000 1.0000
39.1000 0.0000 1.0000
39.1500 0.0000 1.0000
39.2000 1.9666 1.0000
39.2500 2.0000 1.0000
39.3000 0.0000 1.0000
39.3500 0.9530 1.0000
39.4000 1.9914 1.0000
39.4500 2.0296 1.0000
39.5000 1.9570 1.0000
39.5500 3.0403 1.0000
39.6000 1.9966 1.0000
39.6500 2.9993 1.0000
39.7000 0.9893 1.0000
39.7500 1.9857 1.0000
39.8000 0.9969 1.0000
39.8500 1.0286 1.0000
39.9000 0.0000 1.0000
39.9500 1.0017 1.0000
40.0000 3.9906 1.0000
40.0500 0.0000 1.0000
40.1000 0.9870 1.0000
40.1500 2.0045 1.0000
40.2000 2.9647 1.0000
40.2500 1.9847 1.0000
40.3000 0.0000 1.0000
40.3500 0.9675 1.0000
40.4000 2.0071 1.0000
40.4500 0.0000 1.0000
40.5000 2.9623 1.0000
40.5500 1.9679 1.0000
40.6000 2.9762 1.0000
40.6500 0.9943 1.0000
40.7000 2.9680 1.0000
40.7500 1.9738 1.0000
40.8000 1.0039 1.0000
40.8500 0.0000 1.0000
40.9000 0.0000 1.0000
40.9500 5.0021 1.0000
41.0000 0.0000 1.0000
41.0500 0.9960 1.0000
41.1000 2.1244 1.0000
41.1500 0.0000 1.0000
41.2000 3.0118 1.0000
41.2500 1.9752 1.0000
41.3000 0.0000 1.0000
41.3500 1.9821 1.0000
41.4000 2.0065 1.0000
41.4500 2.0073 1.0000
41.5000 1.9712 1.0000
41.5500 2.9720 1.0000
41.6000 1.9720 1.0000
41.6500 1.0190 1.0000
41.7000 0.0000 1.0000
41.7500 0.0000 1.0000
41.8000 4.9551 1.0000
41.8500 0.0000 1.0000
41.9000 3.0024 1.0000
41.9500 5.0515 1.0000
42.0000 0.0000 1.0000
42.0500 0.9943 1.0000
42.1000 0.9895 1.0000
42.1500 1.9749 1.0000
42.2000 2.0066 1.0000
42.2500 2.9922 1.0000
42.3000 2.9631 1.0000
42.3500 0.9629 1.0000
42.4000 1.9540 1.0000
42.4500 0.9953 1.0000
42.5000 0.0000 1.0000
42.5500 0.9964 1.0000
42.6000 1.0019 1.0000
42.6500 1.9844 1.0000
42.7000 0.0000 1.0000
42.7500 2.9930 1.0000
42.8000 2.9794 1.0000
42.8500 4.0029 1.0000
42.9000 0.9890 1.0000
42.9500 0.9886 1.0000
43.0000 2.9463 1.0000
43.0500 0.9965 1.0000
43.1000 1.9575 1.0000
43.1500 0.0000 1.0000
43.2000 2.9940 1.0000
43.2500 0.9938 1.0000
43.3000 2.9779 1.0000
43.3500 0.9889 1.0000
43.4000 0.0000 1.0000
43.4500 3.9929 1.0000
43.5000 2.9791 1.0000
43.5500 0.9530 1.0000
43.6000 0.9776 1.0000
43.6500 0.9890 1.0000
43.7000 2.0069 1.0000
43.7500 0.0000 1.0000
43.8000 1.9736 1.0000
43.8500 1.0200 1.0000
43.9000 2.0399 1.0000
43.9500 2.9784 1.0000
44.0000 2.9588 1.0000
44.0500 0.0000 1.0000
44.1000 5.0018 1.0000
44.1500 2.9704 1.0000
44.2000 0.9941 1.0000
44.2500 6.8691 1.0000
44.3000 7.9570 1.0000
44.3500 6.0101 1.0000
44.4000 6.0161 1.0000
44.4500 3.9966 1.0000
44.5000 3.9961 1.0000
44.5500 3.9967 1.0000
44.6000 3.0203 1.0000
44.6500 1.9930 1.0000
44.7000 0.0000 1.0000
44.7500 3.0092 1.0000
44.8000 2.0062 1.0000
44.8500 3.9670 1.0000
44.9000 0.0000 1.0000
44.9500 2.0272 1.0000
45.0000 1.9799 1.0000
45.0500 4.0230 1.0000
45.1000 3.9778 1.0000
45.1500 0.0000 1.0000
45.2000 0.0000 1.0000
45.2500 0.9965 1.0000
45.3000 2.9543 1.0000
45.3500 1.9888 1.0000
45.4000 3.9973 1.0000
45.4500 1.9867 1.0000
45.5000 0.0000 1.0000
45.5500 1.0178 1.0000
45.6000 0.0000 1.0000
45.6500 2.0139 1.0000
45.7000 0.0000 1.0000
45.7500 4.9853 1.0000
45.8000 0.0000 1.0000
45.8500 0.9901 1.0000
45.9000 2.0426 1.0000
45.9500 3.0032 1.0000
46.0000 3.0403 1.0000
46.0500 0.9835 1.0000
46.1000 2.0202 1.0000
46.1500 1.9740 1.0000
46.2000 1.9988 1.0000
46.2500 1.9595 1.0000
46.3000 0.9755 1.0000
46.3500 1.9818 1.0000
46.4000 2.0019 1.0000
46.4500 3.9959 1.0000
46.5000 2.9850 1.0000
46.5500 1.9485 1.0000
46.6000 2.0033 1.0000
46.6500 2.9473 1.0000
46.7000 0.9844 1.0000
46.7500 3.9627 1.0000
46.8000 0.0000 1.0000
46.8500 0.9928 1.0000
46.9000 0.0000 1.0000
46.9500 5.9201 1.0000
47.0000 0.0000 1.0000
47.0500 0.0000 1.0000
47.1000 1.0037 1.0000
47.1500 2.9922 1.0000
47.2000 0.9873 1.0000
47.2500 3.9428 1.0000
47.3000 1.0200 1.0000
47.3500 3.9767 1.0000
47.4000 1.9531 1.0000
47.4500 1.9897 1.0000
47.5000 2.0223 1.0000
47.5500 2.0266 1.0000
47.6000 0.9980 1.0000
47.6500 2.9697 1.0000
47.7000 2.9899 1.0000
47.7500 2.9996 1.0000
47.8000 3.9824 1.0000
47.8500 0.9827 1.0000
47.9000 0.9939 1.0000
47.9500 0.9781 1.0000
48.0000 2.9881 1.0000
48.0500 0.9893 1.0000
48.1000 0.9943 1.0000
48.1500 3.9540 1.0000
48.2000 2.9356 1.0000
48.2500 3.9965 1.0000
48.3000 0.9883 1.0000
48.3500 1.9978 1.0000
48.4000 0.9977 1.0000
48.4500 2.0180 1.0000
48.5000 2.0102 1.0000
48.5500 3.9949 1.0000
48.6000 1.9536 1.0000
48.6500 1.9959 1.0000
48.7000 2.9659 1.0000
48.7500 0.9869 1.0000
48.8000 4.0140 1.0000
48.8500 1.9538 1.0000
48.9000 1.0045 1.0000
48.9500 1.9878 1.0000
49.0000 0.9984 1.0000
49.0500 3.0250 1.0000
49.1000 1.9586 1.0000
49.1500 1.0309 1.0000
49.2000 1.9809 1.0000
49.2500 4.9389 1.0000
49.3000 0.9835 1.0000
49.3500 1.0178 1.0000
49.4000 0.9901 1.0000
49.4500 0.0000 1.0000
49.5000 0.9866 1.0000
49.5500 3.9984 1.0000
49.6000 3.0057 1.0000
49.6500 0.9948 1.0000
49.7000 4.9626 1.0000
49.7500 2.0284 1.0000
49.8000 1.9756 1.0000
49.8500 0.0000 1.0000
49.9000 0.0000 1.0000
49.9500 0.9776 1.0000
50.0000 2.9719 1.0000
50.0500 3.0073 1.0000
50.1000 4.0428 1.0000
50.1500 1.0089 1.0000
50.2000 1.9774 1.0000
50.2500 0.0000 1.0000
50.3000 1.9966 1.0000
50.3500 1.9975 1.0000
50.4000 2.9663 1.0000
50.4500 2.9952 1.0000
50.5000 0.9996 1.0000
50.5500 5.0022 1.0000
50.6000 1.9546 1.0000
50.6500 2.9042 1.0000
50.7000 2.0084 1.0000
50.7500 2.9816 1.0000
50.8000 0.9766 1.0000
50.8500 4.0791 1.0000
50.9000 0.9893 1.0000
50.9500 2.0203 1.0000
51.0000 0.0000 1.0000
51.0500 2.0090 1.0000
51.1000 1.9714 1.0000
51.1500 0.0000 1.0000
51.2000 0.0000 1.0000
51.2500 2.0250 1.0000
51.3000 1.9844 1.0000
51.3500 1.9535 1.0000
51.4000 0.9690 1.0000
51.4500 1.9859 1.0000
51.5000 2.9738 1.0000
51.5500 1.0002 1.0000
51.6000 1.9703 1.0000
51.6500 0.9654 1.0000
51.7000 0.9820 1.0000
51.7500 1.9686 1.0000
51.8000 1.9614 1.0000
51.8500 2.9740 1.0000
51.9000 1.9897 1.0000
51.9500 2.9724 1.0000
52.0000 0.0000 1.0000
52.0500 0.9969 1.0000
52.1000 0.0000 1.0000
52.1500 0.0000 1.0000
52.2000 1.0025 1.0000
52.2500 0.9827 1.0000
52.3000 0.0000 1.0000
52.3500 0.0000 1.0000
52.4000 2.0264 1.0000
52.4500 1.9723 1.0000
52.5000 1.9815 1.0000
52.5500 2.9906 1.0000
52.6000 2.0175 1.0000
52.6500 1.9759 1.0000
52.7000 5.9248 1.0000
52.7500 1.0001 1.0000
52.8000 0.0000 1.0000
52.8500 2.0086 1.0000
52.9000 1.0009 1.0000
52.9500 0.9979 1.0000
53.0000 2.9904 1.0000
53.0500 0.9865 1.0000
53.1000 0.0000 1.0000
53.1500 1.9868 1.0000
53.2000 0.9891 1.0000
53.2500 3.0213 1.0000
53.3000 2.9682 1.0000
53.3500 2.9936 1.0000
53.4000 2.9885 1.0000
53.4500 0.0000 1.0000
53.5000 1.0338 1.0000
53.5500 0.9839 1.0000
53.6000 4.9964 1.0000
53.6500 0.9629 1.0000
53.7000 2.9732 1.0000
53.7500 1.9712 1.0000
53.8000 4.9629 1.0000
53.8500 1.9745 1.0000
53.9000 3.9540 1.0000
53.9500 2.9694 1.0000
54.0000 2.0004 1.0000
54.0500 2.9894 1.0000
54.1000 0.0000 1.0000
54.1500 1.0208 1.0000
54.2000 0.9961 1.0000
54.2500 4.9838 1.0000
54.3000 2.9642 1.0000
54.3500 1.0114 1.0000
54.4000 3.0197 1.0000
54.4500 1.9895 1.0000
54.5000 1.9856 1.0000
54.5500 2.9632 1.0000
54.6000 0.9728 1.0000
54.6500 1.9985 1.0000
54.7000 2.9383 1.0000
54.7500 1.9907 1.0000
54.8000 3.9226 1.0000
54.8500 0.0000 1.0000
54.9000 2.9790 1.0000
54.9500 6.8989 1.0000
55.0000 0.0000 1.0000
55.0500 2.9639 1.0000
55.1000 0.9851 1.0000
55.1500 0.9984 1.0000
55.2000 0.9851 1.0000
55.2500 1.9950 1.0000
55.3000 1.9889 1.0000
55.3500 0.0000 1.0000
55.4000 1.9856 1.0000
55.4500 2.9736 1.0000
55.5000 2.9801 1.0000
55.5500 2.0212 1.0000
55.6000 0.0000 1.0000
55.6500 4.0339 1.0000
55.7000 3.9610 1.0000
55.7500 1.9984 1.0000
55.8000 0.9890 1.0000
55.8500 1.9847 1.0000
55.9000 0.0000 1.0000
55.9500 0.0000 1.0000
56.0000 0.0000 1.0000
56.0500 0.9782 1.0000
56.1000 0.9990 1.0000
56.1500 1.0051 1.0000
56.2000 1.9683 1.0000
56.2500 0.0000 1.0000
56.3000 1.9696 1.0000
56.3500 0.9994 1.0000
56.4000 4.9452 1.0000
56.4500 2.9972 1.0000
56.5000 1.9640 1.0000
56.5500 1.9636 1.0000
56.6000 3.9887 1.0000
56.6500 1.9835 1.0000
56.7000 2.0365 1.0000
56.7500 4.0025 1.0000
56.8000 1.9874 1.0000
56.8500 0.9701 1.0000
56.9000 0.9955 1.0000
56.9500 0.9997 1.0000
57.0000 1.9803 1.0000
57.0500 3.9934 1.0000
57.1000 1.0169 1.0000
57.1500 1.9966 1.0000
57.2000 3.0514 1.0000
57.2500 2.9688 1.0000
57.3000 0.0000 1.0000
57.3500 0.0000 1.0000
57.4000 2.9577 1.0000
57.4500 0.9862 1.0000
57.5000 2.9810 1.0000
57.5500 2.9660 1.0000
57.6000 0.9957 1.0000
57.6500 2.0117 1.0000
57.7000 0.9629 1.0000
57.7500 0.9919 1.0000
57.8000 2.9975 1.0000
57.8500 0.9949 1.0000
57.9000 0.9996 1.0000
57.9500 3.9697 1.0000
58.0000 3.9705 1.0000
58.0500 0.0000 1.0000
58.1000 0.0000 1.0000
58.1500 1.9861 1.0000
58.2000 1.9924 1.0000
58.2500 0.9903 1.0000
58.3000 4.0100 1.0000
58.3500 1.9969 1.0000
58.4000 1.9789 1.0000
58.4500 0.0000 1.0000
58.5000 0.9851 1.0000
58.5500 4.9644 1.0000
58.6000 4.0244 1.0000
58.6500 1.0028 1.0000
58.7000 0.9918 1.0000
58.7500 2.9807 1.0000
58.8000 1.0001 1.0000
58.8500 5.0126 1.0000
58.9000 3.9682 1.0000
58.9500 2.9557 1.0000
59.0000 3.0150 1.0000
59.0500 0.9703 1.0000
59.1000 1.0134 1.0000
59.1500 1.9793 1.0000
59.2000 0.0000 1.0000
59.2500 2.9979 1.0000
59.3000 2.0040 1.0000
59.3500 0.0000 1.0000
59.4000 0.9965 1.0000
59.4500 3.9428 1.0000
59.5000 0.9926 1.0000
59.5500 3.9870 1.0000
59.6000 1.9783 1.0000
59.6500 1.0106 1.0000
59.7000 2.0274 1.0000
59.7500 1.0109 1.0000
59.8000 1.0078 1.0000
59.8500 2.9630 1.0000
59.9000 3.0218 1.0000
59.9500 0.0000 1.0000
60.0000 1.0011 1.0000
60.0500 1.9573 1.0000
60.1000 2.9583 1.0000
60.1500 2.9625 1.0000
60.2000 1.9713 1.0000
60.2500 0.0000 1.0000
60.3000 4.9978 1.0000
60.3500 2.9728 1.0000
60.4000 2.9848 1.0000
60.4500 3.9158 1.0000
60.5000 1.0122 1.0000
60.5500 3.0219 1.0000
60.6000 2.9809 1.0000
60.6500 0.9728 1.0000
60.7000 4.0090 1.0000
60.7500 1.9872 1.0000
60.8000 5.9494 1.0000
60.8500 0.0000 1.0000
60.9000 3.0065 1.0000
60.9500 2.9424 1.0000
61.0000 1.0286 1.0000
61.0500 0.9885 1.0000
61.1000 0.9701 1.0000
61.1500 0.0000 1.0000
61.2000 0.0000 1.0000
61.2500 2.0029 1.0000
61.3000 0.0000 1.0000
61.3500 1.9903 1.0000
61.4000 1.0237 1.0000
61.4500 1.9826 1.0000
61.5000 1.9997 1.0000
61.5500 2.0040 1.0000
61.6000 0.0000 1.0000
61.6500 6.9610 1.0000
61.7000 0.9802 1.0000
61.7500 2.9794 1.0000
61.8000 0.9794 1.0000
61.8500 1.9855 1.0000
61.9000 1.9869 1.0000
61.9500 4.9229 1.0000
62.0000 3.9605 1.0000
62.0500 2.0090 1.0000
62.1000 2.0006 1.0000
62.1500 0.9934 1.0000
62.2000 1.9790 1.0000
62.2500 2.9814 1.0000
62.3000 3.9784 1.0000
62.3500 3.9845 1.0000
62.4000 2.9834 1.0000
62.4500 1.9961 1.0000
62.5000 3.9732 1.0000
62.5500 2.0174 1.0000
62.6000 0.9629 1.0000
62.6500 0.9958 1.0000
62.7000 5.9718 1.0000
62.7500 1.9934 1.0000
62.8000 0.9835 1.0000
62.8500 0.0000 1.0000
62.9000 3.9763 1.0000
62.9500 4.9919 1.0000
63.0000 1.9777 1.0000
63.0500 3.0420 1.0000
63.1000 6.9370 1.0000
63.1500 4.9327 1.0000
63.2000 1.0089 1.0000
63.2500 2.9587 1.0000
63.3000 1.9951 1.0000
63.3500 2.0188 1.0000
63.4000 5.9885 1.0000
63.4500 1.9863 1.0000
63.5000 0.0000 1.0000
63.5500 1.9758 1.0000
63.6000 0.9791 1.0000
63.6500 2.0090 1.0000
63.7000 1.9975 1.0000
63.7500 2.9702 1.0000
63.8000 2.0170 1.0000
63.8500 3.1239 1.0000
63.9000 2.9829 1.0000
63.9500 4.9771 1.0000
64.0000 1.9735 1.0000
64.0500 7.9323 1.0000
64.1000 5.9194 1.0000
64.1500 3.9623 1.0000
64.2000 3.9955 1.0000
64.2500 0.0000 1.0000
64.3000 3.0560 1.0000
64.3500 3.9591 1.0000
64.4000 4.0110 1.0000
64.4500 6.9714 1.0000
64.5000 2.9316 1.0000
64.5500 2.9906 1.0000
64.6000 5.0322 1.0000
64.6500 3.0046 1.0000
64.7000 5.3070 1.0000
64.7500 8.1256 1.0000
64.8000 3.0524 1.0000
64.8500 4.0111 1.0000
64.9000 2.9948 1.0000
64.9500 6.0134 1.0000
65.0000 5.9214 1.0000
65.0500 4.9990 1.0000
65.1000 8.9685 1.0000
65.1500 7.9545 1.0000
65.2000 8.3040 1.0000
65.2500 11.0359 1.0000
65.3000 10.8604 1.0000
65.3500 3.9271 1.0000
65.4000 12.9946 1.0000
65.4500 12.0681 1.0000
65.5000 14.8868 1.0000
65.5500 10.9827 1.0000
65.6000 21.1533 1.0000
65.6500 22.0731 1.0000
65.7000 24.8681 1.0000
65.7500 22.8944 1.0000
65.8000 30.0279 1.0000
65.8500 38.9919 1.0000
65.9000 49.7319 1.0000
65.9500 50.9765 1.0000
66.0000 66.0928 1.0000
66.0500 77.6579 1.0000
66.1000 157.0744 1.0000
66.1500 506.5851 1.0000
66.2000 2110.3171 1.0000
66.2500 8898.6709 1.0000
66.3000 6317.7969 1.0000
66.3500 323.5070 1.0000
66.4000 93.9455 1.0000
66.4500 51.7908 1.0000
66.5000 33.8381 1.0000
66.5500 27.8835 1.0000
66.6000 14.9782 1.0000
66.6500 14.9258 1.0000
66.7000 11.9280 1.0000
66.7500 21.1535 1.0000
66.8000 10.9481 1.0000
66.8500 12.0270 1.0000
66.9000 8.9371 1.0000
66.9500 11.9761 1.0000
67.0000 11.8646 1.0000
67.0500 8.9472 1.0000
67.1000 14.8682 1.0000
67.1500 8.9086 1.0000
67.2000 4.9743 1.0000
67.2500 6.0075 1.0000
67.3000 8.9227 1.0000
67.3500 5.9685 1.0000
67.4000 3.9952 1.0000
67.4500 1.9899 1.0000
67.5000 4.0173 1.0000
67.5500 3.0211 1.0000
67.6000 9.9835 1.0000
67.6500 2.9862 1.0000
67.7000 2.9670 1.0000
67.7500 2.9991 1.0000
67.8000 7.1302 1.0000
67.8500 9.0085 1.0000
67.9000 6.0134 1.0000
67.9500 2.0176 1.0000
68.0000 1.0026 1.0000
68.0500 8.9970 1.0000
68.1000 4.9968 1.0000
68.1500 3.9458 1.0000
68.2000 5.0282 1.0000
68.2500 2.9682 1.0000
68.3000 1.9601 1.0000
68.3500 6.9671 1.0000
68.4000 2.9926 1.0000
68.4500 4.9415 1.0000
68.5000 4.0200 1.0000
68.5500 4.0035 1.0000
68.6000 0.9965 1.0000
68.6500 5.9599 1.0000
68.7000 2.9600 1.0000
68.7500 1.9488 1.0000
68.8000 4.8987 1.0000
68.8500 4.0257 1.0000
68.9000 6.0197 1.0000
68.9500 5.0158 1.0000
69.0000 3.9649 1.0000
69.0500 1.9909 1.0000
69.1000 2.9928 1.0000
69.1500 2.0368 1.0000
69.2000 4.0022 1.0000
69.2500 8.9609 1.0000
69.3000 3.9216 1.0000
69.3500 1.0092 1.0000
69.4000 4.0015 1.0000
69.4500 3.9590 1.0000
69.5000 2.9830 1.0000
69.5500 1.9777 1.0000
69.6000 2.9775 1.0000
69.6500 2.0215 1.0000
69.7000 1.0037 1.0000
69.7500 0.9794 1.0000
69.8000 4.9648 1.0000
69.8500 1.9990 1.0000
69.9000 3.0042 1.0000
69.9500 2.0005 1.0000
70.0000 4.9438 1.0000
70.0500 2.9731 1.0000
70.1000 3.9361 1.0000
70.1500 1.9851 1.0000
70.2000 5.9837 1.0000
70.2500 4.9473 1.0000
70.3000 3.0108 1.0000
70.3500 0.9890 1.0000
70.4000 2.9879 1.0000
70.4500 1.9938 1.0000
70.5000 1.9778 1.0000
70.5500 3.0044 1.0000
70.6000 0.0000 1.0000
70.6500 5.0007 1.0000
70.7000 3.9252 1.0000
70.7500 1.9963 1.0000
70.8000 3.9965 1.0000
70.8500 0.9890 1.0000
70.9000 6.0017 1.0000
70.9500 4.0214 1.0000
71.0000 2.9674 1.0000
71.0500 3.0036 1.0000
71.1000 3.9954 1.0000
71.1500 2.9663 1.0000
71.2000 2.9684 1.0000
71.2500 1.9597 1.0000
71.3000 0.0000 1.0000
71.3500 3.9573 1.0000
71.4000 2.9857 1.0000
71.4500 3.0298 1.0000
71.5000 4.0392 1.0000
71.5500 1.9648 1.0000
71.6000 3.9517 1.0000
71.6500 0.9774 1.0000
71.7000 4.9902 1.0000
71.7500 5.9374 1.0000
71.8000 0.9716 1.0000
71.8500 3.1401 1.0000
71.9000 5.9597 1.0000
71.9500 0.9736 1.0000
72.0000 3.0289 1.0000
72.0500 4.0256 1.0000
72.1000 1.9959 1.0000
72.1500 1.9883 1.0000
72.2000 2.9830 1.0000
72.2500 1.9586 1.0000
72.3000 0.0000 1.0000
72.3500 1.9885 1.0000
72.4000 3.0019 1.0000
72.4500 1.9839 1.0000
72.5000 0.0000 1.0000
72.5500 1.9645 1.0000
72.6000 3.0122 1.0000
72.6500 0.9835 1.0000
72.7000 0.9870 1.0000
72.7500 0.9873 1.0000
72.8000 1.0109 1.0000
72.8500 0.9914 1.0000
72.9000 1.9692 1.0000
72.9500 1.9989 1.0000
73.0000 2.9926 1.0000
73.0500 1.9745 1.0000
73.1000 0.0000 1.0000
73.1500 1.9725 1.0000
73.2000 0.9701 1.0000
73.2500 0.9794 1.0000
73.3000 0.9967 1.0000
73.3500 0.0000 1.0000
73.4000 1.0055 1.0000
73.4500 0.9911 1.0000
73.5000 0.9899 1.0000
73.5500 3.9723 1.0000
73.6000 0.9937 1.0000
73.6500 0.9824 1.0000
73.7000 0.9816 1.0000
73.7500 3.9635 1.0000
73.8000 0.0000 1.0000
73.8500 0.9928 1.0000
73.9000 1.9818 1.0000
73.9500 4.0238 1.0000
74.0000 1.0171 1.0000
74.0500 3.9889 1.0000
74.1000 2.0030 1.0000
74.1500 3.9681 1.0000
74.2000 3.9847 1.0000
74.2500 1.9729 1.0000
74.3000 1.9598 1.0000
74.3500 2.9708 1.0000
74.4000 0.0000 1.0000
74.4500 1.9864 1.0000
74.5000 1.9806 1.0000
74.5500 3.9848 1.0000
74.6000 0.9826 1.0000
74.6500 1.9716 1.0000
74.7000 4.0010 1.0000
74.7500 5.9975 1.0000
74.8000 4.0618 1.0000
74.8500 4.9954 1.0000
74.9000 1.9956 1.0000
74.9500 2.0004 1.0000
75.0000 0.9965 1.0000
75.0500 0.0000 1.0000
75.1000 1.9930 1.0000
75.1500 1.9870 1.0000
75.2000 3.0216 1.0000
75.2500 4.9677 1.0000
75.3000 0.0000 1.0000
75.3500 1.0053 1.0000
75.4000 4.9958 1.0000
75.4500 1.0105 1.0000
75.5000 2.9918 1.0000
75.5500 0.0000 1.0000
75.6000 0.0000 1.0000
75.6500 1.9779 1.0000
75.7000 0.0000 1.0000
75.7500 3.0090 1.0000
75.8000 0.0000 1.0000
75.8500 1.9813 1.0000
75.9000 2.9465 1.0000
75.9500 0.0000 1.0000
76.0000 1.9759 1.0000
76.0500 4.9210 1.0000
76.1000 0.9781 1.0000
76.1500 3.1150 1.0000
76.2000 4.9533 1.0000
76.2500 3.9535 1.0000
76.3000 1.9937 1.0000
76.3500 5.0370 1.0000
76.4000 3.1302 1.0000
76.4500 2.9734 1.0000
76.5000 0.0000 1.0000
76.5500 2.9778 1.0000
76.6000 4.9548 1.0000
76.6500 4.9585 1.0000
76.7000 1.9527 1.0000
76.7500 0.9935 1.0000
76.8000 1.9759 1.0000
76.8500 2.0022 1.0000
76.9000 1.9816 1.0000
76.9500 1.9742 1.0000
77.0000 6.0045 1.0000
77.0500 1.9756 1.0000
77.1000 2.0070 1.0000
77.1500 3.0429 1.0000
77.2000 3.9534 1.0000
77.2500 0.0000 1.0000
77.3000 4.9619 1.0000
77.3500 4.0121 1.0000
77.4000 2.0422 1.0000
77.4500 0.0000 1.0000
77.5000 1.9904 1.0000
77.5500 4.0018 1.0000
77.6000 1.0411 1.0000
77.6500 2.9978 1.0000
77.7000 0.9993 1.0000
77.7500 0.9990 1.0000
77.8000 0.0000 1.0000
77.8500 0.9990 1.0000
77.9000 4.0252 1.0000
77.9500 2.9622 1.0000
78.0000 5.9898 1.0000
78.0500 1.0049 1.0000
78.1000 2.9919 1.0000
78.1500 1.9711 1.0000
78.2000 2.9894 1.0000
78.2500 1.9723 1.0000
78.3000 3.9328 1.0000
78.3500 0.0000 1.0000
78.4000 1.9856 1.0000
78.4500 0.9909 1.0000
78.5000 3.9380 1.0000
78.5500 2.0036 1.0000
78.6000 0.9870 1.0000
78.6500 0.9654 1.0000
78.7000 0.0000 1.0000
78.7500 1.9611 1.0000
78.8000 3.0129 1.0000
78.8500 0.9817 1.0000
78.9000 2.0091 1.0000
78.9500 2.9558 1.0000
79.0000 2.9883 1.0000
79.0500 1.9803 1.0000
79.1000 1.9695 1.0000
79.1500 2.9954 1.0000
79.2000 1.9999 1.0000
79.2500 0.9984 1.0000
79.3000 3.9610 1.0000
79.3500 3.9510 1.0000
79.4000 2.0071 1.0000
79.4500 2.9659 1.0000
79.5000 0.9746 1.0000
79.5500 1.9945 1.0000
79.6000 0.0000 1.0000
79.6500 2.9718 1.0000
79.7000 1.0092 1.0000
79.7500 1.9546 1.0000
79.8000 3.9389 1.0000
79.8500 6.0031 1.0000
79.9000 1.9750 1.0000
79.9500 2.0188 1.0000
80.0000 1.0149 1.0000
80.0500 1.0014 1.0000
80.1000 2.0176 1.0000
80.1500 3.9702 1.0000
80.2000 1.9882 1.0000
80.2500 0.0000 1.0000
80.3000 2.0253 1.0000
80.3500 0.0000 1.0000
80.4000 2.0096 1.0000
80.4500 3.9204 1.0000
80.5000 1.9574 1.0000
80.5500 0.0000 1.0000
80.6000 4.9856 1.0000
80.6500 0.0000 1.0000
80.7000 4.0192 1.0000
80.7500 1.9649 1.0000
80.8000 0.9983 1.0000
80.8500 1.0177 1.0000
80.9000 2.0102 1.0000
80.9500 0.9918 1.0000
81.0000 3.0067 1.0000
81.0500 0.9530 1.0000
81.1000 4.0382 1.0000
81.1500 1.0033 1.0000
81.2000 3.0327 1.0000
81.2500 2.0072 1.0000
81.3000 3.9746 1.0000
81.3500 3.0043 1.0000
81.4000 4.0175 1.0000
81.4500 2.9539 1.0000
81.5000 3.9464 1.0000
81.5500 4.9708 1.0000
81.6000 1.0060 1.0000
81.6500 3.0289 1.0000
81.7000 2.9752 1.0000
81.7500 4.9661 1.0000
81.8000 3.0068 1.0000
81.8500 2.0008 1.0000
81.9000 5.9774 1.0000
81.9500 5.9430 1.0000
82.0000 3.9644 1.0000
82.0500 2.9928 1.0000
82.1000 1.9962 1.0000
82.1500 4.9595 1.0000
82.2000 4.0037 1.0000
82.2500 1.9768 1.0000
82.3000 1.9887 1.0000
82.3500 0.9975 1.0000
82.4000 3.9455 1.0000
82.4500 2.9958 1.0000
82.5000 0.9848 1.0000
82.5500 0.9658 1.0000
82.6000 3.9767 1.0000
82.6500 0.0000 1.0000
82.7000 0.9932 1.0000
82.7500 2.9984 1.0000
82.8000 1.9876 1.0000
82.8500 0.9947 1.0000
82.9000 2.9624 1.0000
82.9500 3.9947 1.0000
83.0000 0.9710 1.0000
83.0500 0.9960 1.0000
83.1000 0.0000 1.0000
83.1500 1.0110 1.0000
83.2000 3.0012 1.0000
83.2500 0.0000 1.0000
83.3000 1.9965 1.0000
83.3500 0.0000 1.0000
83.4000 5.9450 1.0000
83.4500 1.9976 1.0000
83.5000 0.9954 1.0000
83.5500 3.9803 1.0000
83.6000 5.9464 1.0000
83.6500 1.9577 1.0000
83.7000 2.9934 1.0000
83.7500 1.9944 1.0000
83.8000 4.9949 1.0000
83.8500 4.9305 1.0000
83.9000 4.9421 1.0000
83.9500 0.0000 1.0000
84.0000 2.9823 1.0000
84.0500 0.0000 1.0000
84.1000 1.0081 1.0000
84.1500 8.9901 1.0000
84.2000 1.0109 1.0000
84.2500 1.9970 1.0000
84.3000 0.0000 1.0000
84.3500 1.0109 1.0000
84.4000 1.0012 1.0000
84.4500 0.0000 1.0000
84.5000 0.0000 1.0000
84.5500 4.0160 1.0000
84.6000 5.9331 1.0000
84.6500 0.9695 1.0000
84.7000 0.9863 1.0000
84.7500 2.9878 1.0000
84.8000 0.0000 1.0000
84.8500 0.9965 1.0000
84.9000 3.0342 1.0000
84.9500 0.9947 1.0000
85.0000 0.9890 1.0000
85.0500 2.9725 1.0000
85.1000 0.9706 1.0000
85.1500 3.0297 1.0000
85.2000 3.9998 1.0000
85.2500 4.9192 1.0000
85.3000 4.9485 1.0000
85.3500 1.0039 1.0000
85.4000 0.9875 1.0000
85.4500 0.0000 1.0000
85.5000 0.9919 1.0000
85.5500 0.9995 1.0000
85.6000 3.0236 1.0000
85.6500 0.9979 1.0000
85.7000 5.0517 1.0000
85.7500 1.9940 1.0000
85.8000 1.9802 1.0000
85.8500 4.9692 1.0000
85.9000 0.9873 1.0000
85.9500 1.9885 1.0000
86.0000 3.9628 1.0000
86.0500 0.0000 1.0000
86.1000 1.0039 1.0000
86.1500 0.0000 1.0000
86.2000 0.9831 1.0000
86.2500 2.9796 1.0000
86.3000 0.9849 1.0000
86.3500 0.9792 1.0000
86.4000 1.0000 1.0000
86.4500 1.9803 1.0000
86.5000 2.9716 1.0000
86.5500 1.9881 1.0000
86.6000 1.9735 1.0000
86.6500 1.0021 1.0000
86.7000 1.0192 1.0000
86.7500 2.9384 1.0000
86.8000 4.0160 1.0000
86.8500 4.9227 1.0000
86.9000 1.9655 1.0000
86.9500 0.9629 1.0000
87.0000 0.0000 1.0000
87.0500 2.0003 1.0000
87.1000 2.9866 1.0000
87.1500 4.9311 1.0000
87.2000 5.0397 1.0000
87.2500 0.9977 1.0000
87.3000 4.9570 1.0000
87.3500 2.9875 1.0000
87.4000 1.9814 1.0000
87.4500 1.9843 1.0000
87.5000 2.9920 1.0000
87.5500 0.0000 1.0000
87.6000 2.9872 1.0000
87.6500 0.9848 1.0000
87.7000 0.0000 1.0000
87.7500 3.0030 1.0000
87.8000 1.9297 1.0000
87.8500 2.0017 1.0000
87.9000 0.9993 1.0000
87.9500 1.0009 1.0000
88.0000 6.1430 1.0000
88.0500 4.9339 1.0000
88.1000 2.9901 1.0000
88.1500 2.9856 1.0000
88.2000 0.0000 1.0000
88.2500 0.9530 1.0000
88.3000 2.9804 1.0000
88.3500 0.9940 1.0000
88.4000 2.9437 1.0000
88.4500 5.9506 1.0000
88.5000 2.9547 1.0000
88.5500 3.9831 1.0000
88.6000 1.9750 1.0000
88.6500 5.0290 1.0000
88.7000 1.9888 1.0000
88.7500 1.9919 1.0000
88.8000 0.9893 1.0000
88.8500 3.9448 1.0000
88.9000 1.9798 1.0000
88.9500 4.0177 1.0000
89.0000 1.9830 1.0000
89.0500 6.9490 1.0000
89.1000 0.9948 1.0000
89.1500 0.9919 1.0000
89.2000 1.0010 1.0000
89.2500 5.9868 1.0000
89.3000 1.9986 1.0000
89.3500 1.9873 1.0000
89.4000 0.0000 1.0000
89.4500 0.9922 1.0000
89.5000 1.9944 1.0000
89.5500 4.9859 1.0000
89.6000 2.0072 1.0000
89.6500 1.9794 1.0000
89.7000 5.0054 1.0000
89.7500 0.9839 1.0000
89.8000 3.9498 1.0000
89.8500 5.0254 1.0000
89.9000 3.0092 1.0000
89.9500 1.9990 1.0000
90.0000 2.9931 1.0000
*RAS_INT_END
*RAS_DATA_END