File: CuClQDs/XRD&XRF/20190613/A56_2thetaomega.ras
*RAS_DATA_START
*RAS_HEADER_START
*DISP_FMT_X "%.2f"
*DISP_FMT_Y "%.0f"
*DISP_FULLSCALE "177346.6638979531"
*DISP_LINE_COLOR "255.0000000000"
*DISP_LINE_STYLE "0.0000000000"
*DISP_LINE_WIDTH "0.2500000000"
*DISP_NOTE "測定データ-5"
*DISP_OFFSET_Y "0.0000000000"
*DISP_PEAKSEARCH_UNIT_Y "cps"
*DISP_RANGE_BOTTOM "0.0000000000"
*DISP_RANGE_LEFT "20.0000000000"
*DISP_RANGE_LOGCUTOFF "0.0100000000"
*DISP_RANGE_RIGHT "90.0000000000"
*DISP_RANGE_TOP "177346.6638979531"
*DISP_SCALE_MODE_Y "0.0000000000"
*DISP_TAB_NAME "2θ/ω"
*DISP_TITLE_Y "強度"
*DISP_UNIT_Y "cps"
*DISP_WINDOW_NAME "MSG_MACROENGINE"
*FILE_COMMENT " "
*FILE_MD5 ""
*FILE_MEMO " "
*FILE_OPERATOR "administrator"
*FILE_PART_ID "MEAS_KHP2_00061"
*FILE_SAMPLE "A56"
*FILE_TYPE "RAS_RAW"
*FILE_USERGROUP "システムマネージャ"
*FILE_VERSION "1.0000000000"
*HW_ATTACHMENT_ID "ATT0022"
*HW_ATTACHMENT_NAME "RxRy|RxRy"
*HW_COUNTER_ID-0 "CUT0021"
*HW_COUNTER_ID-1 "CUT0051"
*HW_COUNTER_ID-2 "CUT0020"
*HW_COUNTER_ID-3 "CSL0021"
*HW_COUNTER_ID-4 "CMC0021"
*HW_COUNTER_NAME-0 "SC-70|SC-70"
*HW_COUNTER_NAME-1 "HyPix 3000(H)|HyPix 3000(H)"
*HW_COUNTER_NAME-2 "None|None"
*HW_COUNTER_NAME-3 "BBM|BBM"
*HW_COUNTER_NAME-4 "検出器モノクロメータ|Detector monochromator"
*HW_COUNTER_SELECT_NAME "HyPix 3000(H)|HyPix 3000(H)"
*HW_GONIOMETER_ID "GON0024"
*HW_GONIOMETER_NAME "SmartLab(In-plane)|SmartLab(In-plane)"
*HW_GONIOMETER_RADIUS-0 "90.0"
*HW_GONIOMETER_RADIUS-1 "114.0"
*HW_GONIOMETER_RADIUS-2 "190.0"
*HW_GONIOMETER_RADIUS-3 "300.0"
*HW_GONIOMETER_RADIUS-4 "187.0"
*HW_GONIOMETER_RADIUS-5 "300.0"
*HW_GONIOMETER_RADIUS-6 "113.0"
*HW_GONIOMETER_RADIUS-7 "331.0"
*HW_I_OPT_ID-0 "CBO0021"
*HW_I_OPT_ID-1 "ICR0021"
*HW_I_OPT_ID-2 "ISL0021"
*HW_I_OPT_ID-3 "ISO0021"
*HW_I_OPT_ID-4 "IAD0021"
*HW_I_OPT_ID-5 "IPR0001"
*HW_I_OPT_NAME-0 "CBOユニット|CBO unit"
*HW_I_OPT_NAME-1 "標準入射光学ユニット|Standard incident optical unit"
*HW_I_OPT_NAME-2 "標準入射スリットボックス|Standard incident slit box"
*HW_I_OPT_NAME-3 "入射平行スリット|Incident parallel slit"
*HW_I_OPT_NAME-4 "長手制限スリット|Length limiting slit"
*HW_I_OPT_NAME-5 "None|None"
*HW_R_ATTENUATER_AUTOMODE "0"
*HW_R_OPT_ID-0 "RSS0022"
*HW_R_OPT_ID-1 "RCR0022"
*HW_R_OPT_ID-2 "RSO0021"
*HW_R_OPT_ID-3 "RRS0022"
*HW_R_OPT_ID-4 "ATN0020"
*HW_R_OPT_ID-5 "RFL0021"
*HW_R_OPT_ID-6 "RAD0021"
*HW_R_OPT_NAME-0 "受光スリットボックス1(Zr軸付)|Receiving slit box # 1 (w/ Zr Axis)"
*HW_R_OPT_NAME-1 "標準受光光学ユニット1|Standard receiving unit # 1"
*HW_R_OPT_NAME-2 "標準受光光学ユニット2|Standard receiving optical unit # 2"
*HW_R_OPT_NAME-3 "仮想受光スリット2|Virtual receiving slit #2"
*HW_R_OPT_NAME-4 "無し|None"
*HW_R_OPT_NAME-5 "Cu Kβ|Cu K-beta"
*HW_R_OPT_NAME-6 "調整用受光スリット|Alignment receiving slit"
*HW_SAMPLE_HOLDER_ID "SMP0021"
*HW_SAMPLE_HOLDER_NAME "χφZクレードル|Chi phi Z cradle"
*HW_XG_CURRENT_MAX "200"
*HW_XG_CURRENT_MIN "10"
*HW_XG_CURRENT_RESOLUTION "1"
*HW_XG_CURRENT_UNIT "mA"
*HW_XG_FOCUS "0.4mm x 8mm"
*HW_XG_FOCUS_TYPE "Normal"
*HW_XG_ID "1700"
*HW_XG_NAME "9kW 開放管(45kV 200mA ID:1700)|9kW Rotating anode(45kV 200mA ID:1700)"
*HW_XG_TARGET_ATOMIC_NUMBER "29.0000000000"
*HW_XG_TARGET_NAME "Cu"
*HW_XG_TYPE "Rota"
*HW_XG_VOLTAGE_MAX "45"
*HW_XG_VOLTAGE_MIN "20"
*HW_XG_VOLTAGE_RESOLUTION "1"
*HW_XG_VOLTAGE_UNIT "kV"
*HW_XG_WATT_MAX "9"
*HW_XG_WATT_UNIT "kW"
*HW_XG_WAVE_LENGTH_ALPHA1 "1.540593"
*HW_XG_WAVE_LENGTH_ALPHA2 "1.544414"
*HW_XG_WAVE_LENGTH_BETA "1.392250"
*MEAS_COND_AXIS_NAME-0 "2θ/θ"
*MEAS_COND_AXIS_NAME-1 "2θ"
*MEAS_COND_AXIS_NAME-2 "ω"
*MEAS_COND_AXIS_NAME-3 "χ"
*MEAS_COND_AXIS_NAME-4 "φ"
*MEAS_COND_AXIS_NAME-5 "Z"
*MEAS_COND_AXIS_NAME-6 "Rx"
*MEAS_COND_AXIS_NAME-7 "Ry"
*MEAS_COND_AXIS_NAME-8 "2θ/ω"
*MEAS_COND_AXIS_NAME-9 "2θχ"
*MEAS_COND_AXIS_NAME-10 "2θχ/φ"
*MEAS_COND_AXIS_NAME-11 "α"
*MEAS_COND_AXIS_NAME-12 "β"
*MEAS_COND_AXIS_NAME-13 "θs"
*MEAS_COND_AXIS_NAME-14 "θd"
*MEAS_COND_AXIS_NAME-15 "Ts"
*MEAS_COND_AXIS_NAME-16 "CBO選択スリット"
*MEAS_COND_AXIS_NAME-17 "M"
*MEAS_COND_AXIS_NAME-18 "入射平行スリット"
*MEAS_COND_AXIS_NAME-19 "入射スリット"
*MEAS_COND_AXIS_NAME-20 ""
*MEAS_COND_AXIS_NAME-21 "Zs"
*MEAS_COND_AXIS_NAME-22 "入射光学素子"
*MEAS_COND_AXIS_NAME-23 "ωm"
*MEAS_COND_AXIS_NAME-24 "長手制限スリット"
*MEAS_COND_AXIS_NAME-25 "センタースリット"
*MEAS_COND_AXIS_NAME-26 "フィルター"
*MEAS_COND_AXIS_NAME-27 "受光スリット1"
*MEAS_COND_AXIS_NAME-28 "受光スリット2"
*MEAS_COND_AXIS_NAME-29 "受光光学素子"
*MEAS_COND_AXIS_NAME-30 "受光平行スリット"
*MEAS_COND_AXIS_NAME-31 "調整用受光スリット"
*MEAS_COND_AXIS_NAME-32 ""
*MEAS_COND_AXIS_NAME-33 ""
*MEAS_COND_AXIS_NAME-34 "Zd"
*MEAS_COND_AXIS_NAME-35 "アッテネータ"
*MEAS_COND_AXIS_NAME-36 "検出器モノクロメータ"
*MEAS_COND_AXIS_NAME-37 "モノクロメータスリット"
*MEAS_COND_AXIS_NAME-38 "2θB"
*MEAS_COND_AXIS_NAME-39 ""
*MEAS_COND_AXIS_NAME-40 ""
*MEAS_COND_AXIS_NAME-41 "Zr"
*MEAS_COND_AXIS_NAME-42 "プライマリビーム"
*MEAS_COND_AXIS_NAME_INTERNAL-0 "TwoThetaTheta"
*MEAS_COND_AXIS_NAME_INTERNAL-1 "TwoTheta"
*MEAS_COND_AXIS_NAME_INTERNAL-2 "Omega"
*MEAS_COND_AXIS_NAME_INTERNAL-3 "Chi"
*MEAS_COND_AXIS_NAME_INTERNAL-4 "Phi"
*MEAS_COND_AXIS_NAME_INTERNAL-5 "Z"
*MEAS_COND_AXIS_NAME_INTERNAL-6 "Rx"
*MEAS_COND_AXIS_NAME_INTERNAL-7 "Ry"
*MEAS_COND_AXIS_NAME_INTERNAL-8 "TwoThetaOmega"
*MEAS_COND_AXIS_NAME_INTERNAL-9 "TwoThetaChi"
*MEAS_COND_AXIS_NAME_INTERNAL-10 "TwoThetaChiPhi"
*MEAS_COND_AXIS_NAME_INTERNAL-11 "Alpha"
*MEAS_COND_AXIS_NAME_INTERNAL-12 "Beta"
*MEAS_COND_AXIS_NAME_INTERNAL-13 "ThetaS"
*MEAS_COND_AXIS_NAME_INTERNAL-14 "ThetaD"
*MEAS_COND_AXIS_NAME_INTERNAL-15 "Ts"
*MEAS_COND_AXIS_NAME_INTERNAL-16 "CBO"
*MEAS_COND_AXIS_NAME_INTERNAL-17 "CBO-M"
*MEAS_COND_AXIS_NAME_INTERNAL-18 "IncidentSollerSlit"
*MEAS_COND_AXIS_NAME_INTERNAL-19 "IncidentSlitBox"
*MEAS_COND_AXIS_NAME_INTERNAL-20 "IncidentSlitBox-_Axis"
*MEAS_COND_AXIS_NAME_INTERNAL-21 "Zs"
*MEAS_COND_AXIS_NAME_INTERNAL-22 "IncidentMonochromator"
*MEAS_COND_AXIS_NAME_INTERNAL-23 "IncidentMonochromator-OmegaM"
*MEAS_COND_AXIS_NAME_INTERNAL-24 "IncidentAxdSlit"
*MEAS_COND_AXIS_NAME_INTERNAL-25 "CenterSlit"
*MEAS_COND_AXIS_NAME_INTERNAL-26 "Filter"
*MEAS_COND_AXIS_NAME_INTERNAL-27 "ReceivingSlitBox1"
*MEAS_COND_AXIS_NAME_INTERNAL-28 "ReceivingSlitBox2"
*MEAS_COND_AXIS_NAME_INTERNAL-29 "ReceivingOptics"
*MEAS_COND_AXIS_NAME_INTERNAL-30 "ReceivingSollerSlit"
*MEAS_COND_AXIS_NAME_INTERNAL-31 "ReceivingAxdSlit"
*MEAS_COND_AXIS_NAME_INTERNAL-32 "ReceivingSlitBox1-_Axis"
*MEAS_COND_AXIS_NAME_INTERNAL-33 "ReceivingSlitBox2-_Axis"
*MEAS_COND_AXIS_NAME_INTERNAL-34 "ReceivingSlitBox2-Zd"
*MEAS_COND_AXIS_NAME_INTERNAL-35 "Attenuator"
*MEAS_COND_AXIS_NAME_INTERNAL-36 "CounterMonochromator"
*MEAS_COND_AXIS_NAME_INTERNAL-37 "CounterSlit"
*MEAS_COND_AXIS_NAME_INTERNAL-38 "TwoThetaB"
*MEAS_COND_AXIS_NAME_INTERNAL-39 "AlphaR"
*MEAS_COND_AXIS_NAME_INTERNAL-40 "BetaR"
*MEAS_COND_AXIS_NAME_INTERNAL-41 "ReceivingSlitBox1-Zr"
*MEAS_COND_AXIS_NAME_INTERNAL-42 "IncidentPrimary"
*MEAS_COND_AXIS_NAME_MAGICNO-0 "83951616.0000000000"
*MEAS_COND_AXIS_NAME_MAGICNO-1 "268632064.0000000000"
*MEAS_COND_AXIS_NAME_MAGICNO-2 "268500992.0000000000"
*MEAS_COND_AXIS_NAME_MAGICNO-3 "268500992.0000000000"
*MEAS_COND_AXIS_NAME_MAGICNO-4 "268500992.0000000000"
*MEAS_COND_AXIS_NAME_MAGICNO-5 "285278208.0000000000"
*MEAS_COND_AXIS_NAME_MAGICNO-6 "285278208.0000000000"
*MEAS_COND_AXIS_NAME_MAGICNO-7 "285278208.0000000000"
*MEAS_COND_AXIS_NAME_MAGICNO-8 "83951616.0000000000"
*MEAS_COND_AXIS_NAME_MAGICNO-9 "268632064.0000000000"
*MEAS_COND_AXIS_NAME_MAGICNO-10 "83951616.0000000000"
*MEAS_COND_AXIS_NAME_MAGICNO-11 "17039360.0000000000"
*MEAS_COND_AXIS_NAME_MAGICNO-12 "17039360.0000000000"
*MEAS_COND_AXIS_NAME_MAGICNO-13 "131072.0000000000"
*MEAS_COND_AXIS_NAME_MAGICNO-14 "131072.0000000000"
*MEAS_COND_AXIS_NAME_MAGICNO-15 "318898176.0000000000"
*MEAS_COND_AXIS_NAME_MAGICNO-16 "20971521.0000000000"
*MEAS_COND_AXIS_NAME_MAGICNO-17 "285343744.0000000000"
*MEAS_COND_AXIS_NAME_MAGICNO-18 "20971521.0000000000"
*MEAS_COND_AXIS_NAME_MAGICNO-19 "22020097.0000000000"
*MEAS_COND_AXIS_NAME_MAGICNO-20 "25165824.0000000000"
*MEAS_COND_AXIS_NAME_MAGICNO-21 "318898176.0000000000"
*MEAS_COND_AXIS_NAME_MAGICNO-22 "20971521.0000000000"
*MEAS_COND_AXIS_NAME_MAGICNO-23 "285343744.0000000000"
*MEAS_COND_AXIS_NAME_MAGICNO-24 "20971521.0000000000"
*MEAS_COND_AXIS_NAME_MAGICNO-25 "20971521.0000000000"
*MEAS_COND_AXIS_NAME_MAGICNO-26 "20971521.0000000000"
*MEAS_COND_AXIS_NAME_MAGICNO-27 "23068673.0000000000"
*MEAS_COND_AXIS_NAME_MAGICNO-28 "23068673.0000000000"
*MEAS_COND_AXIS_NAME_MAGICNO-29 "20971521.0000000000"
*MEAS_COND_AXIS_NAME_MAGICNO-30 "20971521.0000000000"
*MEAS_COND_AXIS_NAME_MAGICNO-31 "20971521.0000000000"
*MEAS_COND_AXIS_NAME_MAGICNO-32 "25165824.0000000000"
*MEAS_COND_AXIS_NAME_MAGICNO-33 "25165824.0000000000"
*MEAS_COND_AXIS_NAME_MAGICNO-34 "285343744.0000000000"
*MEAS_COND_AXIS_NAME_MAGICNO-35 "0.0000000000"
*MEAS_COND_AXIS_NAME_MAGICNO-36 "20971521.0000000000"
*MEAS_COND_AXIS_NAME_MAGICNO-37 "20971521.0000000000"
*MEAS_COND_AXIS_NAME_MAGICNO-38 "17039360.0000000000"
*MEAS_COND_AXIS_NAME_MAGICNO-39 "8388608.0000000000"
*MEAS_COND_AXIS_NAME_MAGICNO-40 "8388608.0000000000"
*MEAS_COND_AXIS_NAME_MAGICNO-41 "285343744.0000000000"
*MEAS_COND_AXIS_NAME_MAGICNO-42 "20971521.0000000000"
*MEAS_COND_AXIS_OFFSET-0 "-"
*MEAS_COND_AXIS_OFFSET-1 "0.8440000000"
*MEAS_COND_AXIS_OFFSET-2 "1.5173000000"
*MEAS_COND_AXIS_OFFSET-3 "0.0000000000"
*MEAS_COND_AXIS_OFFSET-4 "0.0000000000"
*MEAS_COND_AXIS_OFFSET-5 "-"
*MEAS_COND_AXIS_OFFSET-6 "-"
*MEAS_COND_AXIS_OFFSET-7 "-"
*MEAS_COND_AXIS_OFFSET-8 "-"
*MEAS_COND_AXIS_OFFSET-9 "0.0000000000"
*MEAS_COND_AXIS_OFFSET-10 "-"
*MEAS_COND_AXIS_OFFSET-11 "-"
*MEAS_COND_AXIS_OFFSET-12 "-"
*MEAS_COND_AXIS_OFFSET-13 "1.5173000000"
*MEAS_COND_AXIS_OFFSET-14 "-0.6733000000"
*MEAS_COND_AXIS_OFFSET-15 "-"
*MEAS_COND_AXIS_OFFSET-16 "-"
*MEAS_COND_AXIS_OFFSET-17 "-"
*MEAS_COND_AXIS_OFFSET-18 "-"
*MEAS_COND_AXIS_OFFSET-19 "-"
*MEAS_COND_AXIS_OFFSET-20 "-"
*MEAS_COND_AXIS_OFFSET-21 "-"
*MEAS_COND_AXIS_OFFSET-22 "-"
*MEAS_COND_AXIS_OFFSET-23 "-"
*MEAS_COND_AXIS_OFFSET-24 "-"
*MEAS_COND_AXIS_OFFSET-25 "-"
*MEAS_COND_AXIS_OFFSET-26 "-"
*MEAS_COND_AXIS_OFFSET-27 "-"
*MEAS_COND_AXIS_OFFSET-28 "-"
*MEAS_COND_AXIS_OFFSET-29 "-"
*MEAS_COND_AXIS_OFFSET-30 "-"
*MEAS_COND_AXIS_OFFSET-31 "-"
*MEAS_COND_AXIS_OFFSET-32 "-"
*MEAS_COND_AXIS_OFFSET-33 "-"
*MEAS_COND_AXIS_OFFSET-34 "-"
*MEAS_COND_AXIS_OFFSET-35 "-"
*MEAS_COND_AXIS_OFFSET-36 "-"
*MEAS_COND_AXIS_OFFSET-37 "-"
*MEAS_COND_AXIS_OFFSET-38 "-"
*MEAS_COND_AXIS_OFFSET-39 "0.0000000000"
*MEAS_COND_AXIS_OFFSET-40 "0.0000000000"
*MEAS_COND_AXIS_OFFSET-41 "-"
*MEAS_COND_AXIS_OFFSET-42 "-"
*MEAS_COND_AXIS_POSITION-0 "20.0000000000"
*MEAS_COND_AXIS_POSITION-1 "20.0000000000"
*MEAS_COND_AXIS_POSITION-2 "10.0000000000"
*MEAS_COND_AXIS_POSITION-3 "0.6110000000"
*MEAS_COND_AXIS_POSITION-4 "-2.4900000000"
*MEAS_COND_AXIS_POSITION-5 "-0.5154000000"
*MEAS_COND_AXIS_POSITION-6 "0.0000000000"
*MEAS_COND_AXIS_POSITION-7 "0.0000000000"
*MEAS_COND_AXIS_POSITION-8 "20.0000000000"
*MEAS_COND_AXIS_POSITION-9 "0.0000000000"
*MEAS_COND_AXIS_POSITION-10 "0.0000000000"
*MEAS_COND_AXIS_POSITION-11 "90.0000000000"
*MEAS_COND_AXIS_POSITION-12 "0.0000000000"
*MEAS_COND_AXIS_POSITION-13 "10.0000000000"
*MEAS_COND_AXIS_POSITION-14 "10.0000000000"
*MEAS_COND_AXIS_POSITION-15 "-5.8605600000"
*MEAS_COND_AXIS_POSITION-16 "PB"
*MEAS_COND_AXIS_POSITION-17 "0.0000000000"
*MEAS_COND_AXIS_POSITION-18 "Soller_slit_open_s"
*MEAS_COND_AXIS_POSITION-19 "0.500mm"
*MEAS_COND_AXIS_POSITION-20 "0.5000000000"
*MEAS_COND_AXIS_POSITION-21 "-1.6178100000"
*MEAS_COND_AXIS_POSITION-22 "Ge(220)x2"
*MEAS_COND_AXIS_POSITION-23 "0.0000000000"
*MEAS_COND_AXIS_POSITION-24 "2.0mm"
*MEAS_COND_AXIS_POSITION-25 "None"
*MEAS_COND_AXIS_POSITION-26 "None"
*MEAS_COND_AXIS_POSITION-27 "0.500mm"
*MEAS_COND_AXIS_POSITION-28 "0.500mm"
*MEAS_COND_AXIS_POSITION-29 "PSA_open"
*MEAS_COND_AXIS_POSITION-30 "Soller_slit_5.0deg"
*MEAS_COND_AXIS_POSITION-31 "None"
*MEAS_COND_AXIS_POSITION-32 "0.5000000000"
*MEAS_COND_AXIS_POSITION-33 "0.5000000000"
*MEAS_COND_AXIS_POSITION-34 "0.0000000000"
*MEAS_COND_AXIS_POSITION-35 "-"
*MEAS_COND_AXIS_POSITION-36 "No_unit"
*MEAS_COND_AXIS_POSITION-37 "None"
*MEAS_COND_AXIS_POSITION-38 "20.0000000000"
*MEAS_COND_AXIS_POSITION-39 "0.0000000000"
*MEAS_COND_AXIS_POSITION-40 "0.0000000000"
*MEAS_COND_AXIS_POSITION-41 "-0.3859400000"
*MEAS_COND_AXIS_POSITION-42 "None"
*MEAS_COND_AXIS_UNIT-0 "deg"
*MEAS_COND_AXIS_UNIT-1 "deg"
*MEAS_COND_AXIS_UNIT-2 "deg"
*MEAS_COND_AXIS_UNIT-3 "deg"
*MEAS_COND_AXIS_UNIT-4 "deg"
*MEAS_COND_AXIS_UNIT-5 "mm"
*MEAS_COND_AXIS_UNIT-6 "deg"
*MEAS_COND_AXIS_UNIT-7 "deg"
*MEAS_COND_AXIS_UNIT-8 "deg"
*MEAS_COND_AXIS_UNIT-9 "deg"
*MEAS_COND_AXIS_UNIT-10 "deg"
*MEAS_COND_AXIS_UNIT-11 "deg"
*MEAS_COND_AXIS_UNIT-12 "deg"
*MEAS_COND_AXIS_UNIT-13 "deg"
*MEAS_COND_AXIS_UNIT-14 "deg"
*MEAS_COND_AXIS_UNIT-15 "mm"
*MEAS_COND_AXIS_UNIT-16 ""
*MEAS_COND_AXIS_UNIT-17 "pulse"
*MEAS_COND_AXIS_UNIT-18 ""
*MEAS_COND_AXIS_UNIT-19 ""
*MEAS_COND_AXIS_UNIT-20 "mm"
*MEAS_COND_AXIS_UNIT-21 "mm"
*MEAS_COND_AXIS_UNIT-22 ""
*MEAS_COND_AXIS_UNIT-23 "pulse"
*MEAS_COND_AXIS_UNIT-24 ""
*MEAS_COND_AXIS_UNIT-25 ""
*MEAS_COND_AXIS_UNIT-26 ""
*MEAS_COND_AXIS_UNIT-27 ""
*MEAS_COND_AXIS_UNIT-28 ""
*MEAS_COND_AXIS_UNIT-29 ""
*MEAS_COND_AXIS_UNIT-30 ""
*MEAS_COND_AXIS_UNIT-31 ""
*MEAS_COND_AXIS_UNIT-32 "mm"
*MEAS_COND_AXIS_UNIT-33 "mm"
*MEAS_COND_AXIS_UNIT-34 "mm"
*MEAS_COND_AXIS_UNIT-35 ""
*MEAS_COND_AXIS_UNIT-36 ""
*MEAS_COND_AXIS_UNIT-37 ""
*MEAS_COND_AXIS_UNIT-38 "deg"
*MEAS_COND_AXIS_UNIT-39 "deg"
*MEAS_COND_AXIS_UNIT-40 "deg"
*MEAS_COND_AXIS_UNIT-41 "mm"
*MEAS_COND_AXIS_UNIT-42 ""
*MEAS_COND_COUNTER_CNTLOSS_CORR "0.0000000000"
*MEAS_COND_COUNTER_TAUDIFF "0.0000000000"
*MEAS_COND_COUNTER_TAUINT "0.0000000000"
*MEAS_COND_COUNTER_TEMP_CONDITION "NORMAL"
*MEAS_COND_IRRADIATION_MODE "OFF"
*MEAS_COND_IRRADIATION_WIDTH ""
*MEAS_COND_OPT_ATTR "高分解能平行ビームGe(220)x2/受光スリット"
*MEAS_COND_OPT_NAME "@高分解能PB-Ge(220)x2"
*MEAS_COND_UNSYMMETRIC_MODE "OFF"
*MEAS_COND_XG_CURRENT "200.0000000000"
*MEAS_COND_XG_VOLTAGE "45.0000000000"
*MEAS_COND_XG_WAVE_TYPE "Ka1"
*MEAS_DATA_COUNT "7001.0000000000"
*MEAS_SCAN_AXIS_X "2θ/ω"
*MEAS_SCAN_AXIS_X_INTERNAL "TwoThetaOmega"
*MEAS_SCAN_END_TIME "06/13/19 17:02:24"
*MEAS_SCAN_MODE "CONTINUOUS"
*MEAS_SCAN_MONITOR "0"
*MEAS_SCAN_RESOLUTION_X "0.0002"
*MEAS_SCAN_SPEED "3.056366"
*MEAS_SCAN_SPEED_UNIT "deg/min"
*MEAS_SCAN_SPEED_USER "3.000000"
*MEAS_SCAN_START "20.0000000000"
*MEAS_SCAN_START_TIME "06/13/19 16:38:52"
*MEAS_SCAN_STEP "0.0100000000"
*MEAS_SCAN_STOP "90.0000000000"
*MEAS_SCAN_UNIT_X "deg"
*MEAS_SCAN_UNIT_Y "counts"
*RAS_HEADER_END
*RAS_INT_START
20.0000 0.9675 1.0000
20.0500 3.9556 1.0000
20.1000 2.9706 1.0000
20.1500 0.9710 1.0000
20.2000 0.9930 1.0000
20.2500 1.0172 1.0000
20.3000 0.9531 1.0000
20.3500 1.9685 1.0000
20.4000 1.9896 1.0000
20.4500 1.0045 1.0000
20.5000 0.0000 1.0000
20.5500 0.9852 1.0000
20.6000 0.0000 1.0000
20.6500 0.9953 1.0000
20.7000 0.9855 1.0000
20.7500 1.0053 1.0000
20.8000 1.9899 1.0000
20.8500 0.0000 1.0000
20.9000 0.9841 1.0000
20.9500 1.9861 1.0000
21.0000 2.9981 1.0000
21.0500 0.9781 1.0000
21.1000 1.9979 1.0000
21.1500 1.9738 1.0000
21.2000 5.0058 1.0000
21.2500 5.9502 1.0000
21.3000 4.9702 1.0000
21.3500 0.9901 1.0000
21.4000 0.0000 1.0000
21.4500 1.0251 1.0000
21.5000 1.9920 1.0000
21.5500 1.9889 1.0000
21.6000 2.0091 1.0000
21.6500 0.9954 1.0000
21.7000 0.0000 1.0000
21.7500 0.9982 1.0000
21.8000 0.0000 1.0000
21.8500 0.9794 1.0000
21.9000 0.9829 1.0000
21.9500 1.9946 1.0000
22.0000 0.0000 1.0000
22.0500 0.9924 1.0000
22.1000 3.9506 1.0000
22.1500 4.0230 1.0000
22.2000 0.9977 1.0000
22.2500 2.0054 1.0000
22.3000 0.0000 1.0000
22.3500 1.9821 1.0000
22.4000 0.9894 1.0000
22.4500 1.9718 1.0000
22.5000 0.0000 1.0000
22.5500 0.9890 1.0000
22.6000 2.0165 1.0000
22.6500 1.0022 1.0000
22.7000 0.9991 1.0000
22.7500 3.0201 1.0000
22.8000 0.9870 1.0000
22.8500 1.9838 1.0000
22.9000 4.0247 1.0000
22.9500 0.0000 1.0000
23.0000 2.0055 1.0000
23.0500 0.0000 1.0000
23.1000 0.0000 1.0000
23.1500 1.9833 1.0000
23.2000 0.0000 1.0000
23.2500 2.9852 1.0000
23.3000 0.0000 1.0000
23.3500 0.9675 1.0000
23.4000 2.9966 1.0000
23.4500 8.0276 1.0000
23.5000 2.9513 1.0000
23.5500 1.9760 1.0000
23.6000 2.9990 1.0000
23.6500 1.9835 1.0000
23.7000 0.9609 1.0000
23.7500 1.0199 1.0000
23.8000 0.9988 1.0000
23.8500 1.0049 1.0000
23.9000 0.9866 1.0000
23.9500 0.9840 1.0000
24.0000 2.9689 1.0000
24.0500 2.0199 1.0000
24.1000 0.9675 1.0000
24.1500 0.0000 1.0000
24.2000 0.0000 1.0000
24.2500 2.0353 1.0000
24.3000 1.0019 1.0000
24.3500 0.0000 1.0000
24.4000 0.9989 1.0000
24.4500 2.0081 1.0000
24.5000 0.9929 1.0000
24.5500 4.9554 1.0000
24.6000 0.9841 1.0000
24.6500 1.9630 1.0000
24.7000 3.0135 1.0000
24.7500 0.9899 1.0000
24.8000 0.9912 1.0000
24.8500 2.0091 1.0000
24.9000 0.0000 1.0000
24.9500 1.9804 1.0000
25.0000 0.9959 1.0000
25.0500 0.0000 1.0000
25.1000 0.9958 1.0000
25.1500 0.0000 1.0000
25.2000 1.0025 1.0000
25.2500 1.9916 1.0000
25.3000 0.9948 1.0000
25.3500 1.9632 1.0000
25.4000 0.0000 1.0000
25.4500 1.9966 1.0000
25.5000 1.9840 1.0000
25.5500 4.0057 1.0000
25.6000 0.9774 1.0000
25.6500 0.9839 1.0000
25.7000 0.0000 1.0000
25.7500 0.0000 1.0000
25.8000 0.9948 1.0000
25.8500 1.0010 1.0000
25.9000 1.0027 1.0000
25.9500 0.9682 1.0000
26.0000 0.9978 1.0000
26.0500 2.0051 1.0000
26.1000 1.0029 1.0000
26.1500 3.0166 1.0000
26.2000 1.9875 1.0000
26.2500 0.9865 1.0000
26.3000 2.0092 1.0000
26.3500 0.0000 1.0000
26.4000 1.9823 1.0000
26.4500 0.0000 1.0000
26.5000 0.9893 1.0000
26.5500 0.9866 1.0000
26.6000 5.9707 1.0000
26.6500 0.0000 1.0000
26.7000 1.9961 1.0000
26.7500 0.0000 1.0000
26.8000 1.9860 1.0000
26.8500 0.9990 1.0000
26.9000 1.9861 1.0000
26.9500 4.0131 1.0000
27.0000 3.9790 1.0000
27.0500 0.0000 1.0000
27.1000 0.9787 1.0000
27.1500 1.0019 1.0000
27.2000 1.0092 1.0000
27.2500 1.9885 1.0000
27.3000 4.9986 1.0000
27.3500 1.9745 1.0000
27.4000 4.9910 1.0000
27.4500 3.0099 1.0000
27.5000 0.9843 1.0000
27.5500 0.9717 1.0000
27.6000 1.0294 1.0000
27.6500 1.9549 1.0000
27.7000 0.9881 1.0000
27.7500 2.9584 1.0000
27.8000 3.9829 1.0000
27.8500 0.9924 1.0000
27.9000 3.9801 1.0000
27.9500 0.9912 1.0000
28.0000 0.9949 1.0000
28.0500 1.9844 1.0000
28.1000 0.0000 1.0000
28.1500 2.9640 1.0000
28.2000 1.9796 1.0000
28.2500 3.9414 1.0000
28.3000 1.9840 1.0000
28.3500 2.9993 1.0000
28.4000 1.9802 1.0000
28.4500 0.0000 1.0000
28.5000 2.9238 1.0000
28.5500 3.0398 1.0000
28.6000 3.0128 1.0000
28.6500 1.9927 1.0000
28.7000 3.0192 1.0000
28.7500 1.9937 1.0000
28.8000 5.9362 1.0000
28.8500 2.9767 1.0000
28.9000 4.0175 1.0000
28.9500 4.9507 1.0000
29.0000 1.9982 1.0000
29.0500 3.9963 1.0000
29.1000 5.0078 1.0000
29.1500 4.0102 1.0000
29.2000 3.0177 1.0000
29.2500 4.0068 1.0000
29.3000 7.9883 1.0000
29.3500 0.9983 1.0000
29.4000 1.0282 1.0000
29.4500 2.9754 1.0000
29.5000 1.9806 1.0000
29.5500 3.9608 1.0000
29.6000 1.9604 1.0000
29.6500 2.9962 1.0000
29.7000 2.9732 1.0000
29.7500 5.9496 1.0000
29.8000 2.9687 1.0000
29.8500 4.9927 1.0000
29.9000 1.0211 1.0000
29.9500 3.9417 1.0000
30.0000 4.0024 1.0000
30.0500 0.9906 1.0000
30.1000 2.9697 1.0000
30.1500 4.9595 1.0000
30.2000 3.9782 1.0000
30.2500 4.9216 1.0000
30.3000 4.9739 1.0000
30.3500 3.9510 1.0000
30.4000 4.0158 1.0000
30.4500 2.9993 1.0000
30.5000 4.0176 1.0000
30.5500 7.8792 1.0000
30.6000 9.9948 1.0000
30.6500 8.9537 1.0000
30.7000 4.0062 1.0000
30.7500 9.9702 1.0000
30.8000 5.9811 1.0000
30.8500 6.9009 1.0000
30.9000 10.9768 1.0000
30.9500 8.9815 1.0000
31.0000 11.9384 1.0000
31.0500 7.9496 1.0000
31.1000 15.2915 1.0000
31.1500 14.9845 1.0000
31.2000 12.9191 1.0000
31.2500 25.0034 1.0000
31.3000 19.8781 1.0000
31.3500 23.9165 1.0000
31.4000 27.2289 1.0000
31.4500 35.9420 1.0000
31.5000 36.8146 1.0000
31.5500 54.9485 1.0000
31.6000 66.8417 1.0000
31.6500 123.7828 1.0000
31.7000 3156.0244 1.0000
31.7500 5539.3647 1.0000
31.8000 29012.6680 1.0000
31.8500 9959.2324 1.0000
31.9000 3596.4851 1.0000
31.9500 84.9595 1.0000
32.0000 42.0201 1.0000
32.0500 27.1957 1.0000
32.1000 14.8735 1.0000
32.1500 16.9418 1.0000
32.2000 20.8029 1.0000
32.2500 13.9474 1.0000
32.3000 18.1787 1.0000
32.3500 13.0037 1.0000
32.4000 11.0007 1.0000
32.4500 4.9807 1.0000
32.5000 8.9794 1.0000
32.5500 5.0332 1.0000
32.6000 9.9344 1.0000
32.6500 5.0116 1.0000
32.7000 5.9822 1.0000
32.7500 5.9876 1.0000
32.8000 7.9683 1.0000
32.8500 15.9168 1.0000
32.9000 5.0241 1.0000
32.9500 7.0061 1.0000
33.0000 5.0017 1.0000
33.0500 11.0829 1.0000
33.1000 5.1765 1.0000
33.1500 5.9447 1.0000
33.2000 5.9712 1.0000
33.2500 5.0056 1.0000
33.3000 6.0455 1.0000
33.3500 5.9723 1.0000
33.4000 4.9993 1.0000
33.4500 4.9769 1.0000
33.5000 3.0225 1.0000
33.5500 3.9828 1.0000
33.6000 4.0097 1.0000
33.6500 6.9773 1.0000
33.7000 2.0145 1.0000
33.7500 0.9871 1.0000
33.8000 5.2914 1.0000
33.8500 8.0055 1.0000
33.9000 1.9999 1.0000
33.9500 1.9873 1.0000
34.0000 3.0522 1.0000
34.0500 4.9567 1.0000
34.1000 3.0042 1.0000
34.1500 2.0204 1.0000
34.2000 2.9628 1.0000
34.2500 3.9607 1.0000
34.3000 9.0942 1.0000
34.3500 3.0112 1.0000
34.4000 1.0098 1.0000
34.4500 1.0087 1.0000
34.5000 4.0002 1.0000
34.5500 2.0107 1.0000
34.6000 1.9797 1.0000
34.6500 2.0120 1.0000
34.7000 3.9661 1.0000
34.7500 3.9841 1.0000
34.8000 3.9434 1.0000
34.8500 0.9919 1.0000
34.9000 1.0208 1.0000
34.9500 0.0000 1.0000
35.0000 0.9968 1.0000
35.0500 0.9889 1.0000
35.1000 2.0238 1.0000
35.1500 0.0000 1.0000
35.2000 0.9728 1.0000
35.2500 2.9682 1.0000
35.3000 2.0458 1.0000
35.3500 4.0057 1.0000
35.4000 1.9878 1.0000
35.4500 0.9899 1.0000
35.5000 3.9519 1.0000
35.5500 5.0026 1.0000
35.6000 1.9949 1.0000
35.6500 1.9850 1.0000
35.7000 2.9755 1.0000
35.7500 3.0027 1.0000
35.8000 1.9871 1.0000
35.8500 2.0108 1.0000
35.9000 1.0080 1.0000
35.9500 1.9485 1.0000
36.0000 6.9902 1.0000
36.0500 2.0050 1.0000
36.1000 0.9861 1.0000
36.1500 0.9935 1.0000
36.2000 0.0000 1.0000
36.2500 2.9627 1.0000
36.3000 4.9434 1.0000
36.3500 0.9988 1.0000
36.4000 1.0308 1.0000
36.4500 3.9938 1.0000
36.5000 1.0163 1.0000
36.5500 4.9146 1.0000
36.6000 0.0000 1.0000
36.6500 2.0006 1.0000
36.7000 0.9978 1.0000
36.7500 3.0057 1.0000
36.8000 0.0000 1.0000
36.8500 1.9638 1.0000
36.9000 0.9992 1.0000
36.9500 0.0000 1.0000
37.0000 4.9566 1.0000
37.0500 0.9701 1.0000
37.1000 2.0298 1.0000
37.1500 1.0128 1.0000
37.2000 2.9909 1.0000
37.2500 3.9666 1.0000
37.3000 1.9796 1.0000
37.3500 0.0000 1.0000
37.4000 4.9654 1.0000
37.4500 3.0001 1.0000
37.5000 3.0020 1.0000
37.5500 1.0149 1.0000
37.6000 2.0319 1.0000
37.6500 1.0039 1.0000
37.7000 4.0236 1.0000
37.7500 1.9899 1.0000
37.8000 0.9792 1.0000
37.8500 2.9820 1.0000
37.9000 2.0102 1.0000
37.9500 1.0306 1.0000
38.0000 3.0022 1.0000
38.0500 4.9732 1.0000
38.1000 0.9928 1.0000
38.1500 6.8887 1.0000
38.2000 4.9887 1.0000
38.2500 6.0172 1.0000
38.3000 0.9926 1.0000
38.3500 4.0191 1.0000
38.4000 0.0000 1.0000
38.4500 2.9685 1.0000
38.5000 1.9654 1.0000
38.5500 2.0055 1.0000
38.6000 4.0012 1.0000
38.6500 0.0000 1.0000
38.7000 0.0000 1.0000
38.7500 0.0000 1.0000
38.8000 1.9765 1.0000
38.8500 4.9440 1.0000
38.9000 3.0111 1.0000
38.9500 2.9981 1.0000
39.0000 0.9998 1.0000
39.0500 2.9930 1.0000
39.1000 3.9566 1.0000
39.1500 0.9889 1.0000
39.2000 0.0000 1.0000
39.2500 2.9953 1.0000
39.3000 2.9427 1.0000
39.3500 1.9925 1.0000
39.4000 3.0027 1.0000
39.4500 0.0000 1.0000
39.5000 1.0029 1.0000
39.5500 0.0000 1.0000
39.6000 3.0114 1.0000
39.6500 0.0000 1.0000
39.7000 1.9815 1.0000
39.7500 1.0009 1.0000
39.8000 2.9958 1.0000
39.8500 1.0059 1.0000
39.9000 0.0000 1.0000
39.9500 2.0369 1.0000
40.0000 2.9475 1.0000
40.0500 3.9735 1.0000
40.1000 0.0000 1.0000
40.1500 0.9791 1.0000
40.2000 0.9855 1.0000
40.2500 1.9928 1.0000
40.3000 0.9921 1.0000
40.3500 1.0019 1.0000
40.4000 1.9771 1.0000
40.4500 5.9317 1.0000
40.5000 3.9684 1.0000
40.5500 0.9829 1.0000
40.6000 3.9491 1.0000
40.6500 3.9860 1.0000
40.7000 1.0093 1.0000
40.7500 0.0000 1.0000
40.8000 0.0000 1.0000
40.8500 1.9639 1.0000
40.9000 2.0199 1.0000
40.9500 4.0512 1.0000
41.0000 0.0000 1.0000
41.0500 2.0094 1.0000
41.1000 1.9558 1.0000
41.1500 3.0133 1.0000
41.2000 0.0000 1.0000
41.2500 2.9758 1.0000
41.3000 2.9787 1.0000
41.3500 0.0000 1.0000
41.4000 0.9654 1.0000
41.4500 0.9943 1.0000
41.5000 2.0096 1.0000
41.5500 0.9814 1.0000
41.6000 1.0020 1.0000
41.6500 3.0082 1.0000
41.7000 3.9223 1.0000
41.7500 4.9995 1.0000
41.8000 1.0411 1.0000
41.8500 2.9764 1.0000
41.9000 1.9864 1.0000
41.9500 1.0033 1.0000
42.0000 1.9796 1.0000
42.0500 2.9878 1.0000
42.1000 0.9746 1.0000
42.1500 1.9675 1.0000
42.2000 1.9916 1.0000
42.2500 0.9863 1.0000
42.3000 4.9317 1.0000
42.3500 1.9999 1.0000
42.4000 2.0264 1.0000
42.4500 0.0000 1.0000
42.5000 1.9915 1.0000
42.5500 2.0105 1.0000
42.6000 1.0001 1.0000
42.6500 0.9939 1.0000
42.7000 2.9556 1.0000
42.7500 0.9926 1.0000
42.8000 2.0099 1.0000
42.8500 2.9984 1.0000
42.9000 0.9898 1.0000
42.9500 2.9743 1.0000
43.0000 1.0101 1.0000
43.0500 1.0060 1.0000
43.1000 1.0134 1.0000
43.1500 1.9865 1.0000
43.2000 0.9875 1.0000
43.2500 0.9736 1.0000
43.3000 4.0019 1.0000
43.3500 2.0191 1.0000
43.4000 0.9942 1.0000
43.4500 1.0017 1.0000
43.5000 0.9939 1.0000
43.5500 4.9827 1.0000
43.6000 1.9605 1.0000
43.6500 1.9911 1.0000
43.7000 1.9694 1.0000
43.7500 1.9764 1.0000
43.8000 4.9405 1.0000
43.8500 0.0000 1.0000
43.9000 0.0000 1.0000
43.9500 3.9996 1.0000
44.0000 1.9973 1.0000
44.0500 2.9613 1.0000
44.1000 2.0326 1.0000
44.1500 7.9967 1.0000
44.2000 2.9463 1.0000
44.2500 5.9897 1.0000
44.3000 6.9797 1.0000
44.3500 4.9830 1.0000
44.4000 7.0138 1.0000
44.4500 4.0345 1.0000
44.5000 3.0051 1.0000
44.5500 4.9841 1.0000
44.6000 1.9781 1.0000
44.6500 5.9863 1.0000
44.7000 0.9958 1.0000
44.7500 3.9878 1.0000
44.8000 3.9963 1.0000
44.8500 0.0000 1.0000
44.9000 1.9742 1.0000
44.9500 2.9777 1.0000
45.0000 0.0000 1.0000
45.0500 0.9994 1.0000
45.1000 1.9850 1.0000
45.1500 0.0000 1.0000
45.2000 3.9608 1.0000
45.2500 0.9906 1.0000
45.3000 1.9947 1.0000
45.3500 2.9854 1.0000
45.4000 4.0136 1.0000
45.4500 2.9875 1.0000
45.5000 3.0083 1.0000
45.5500 0.0000 1.0000
45.6000 4.9949 1.0000
45.6500 1.9861 1.0000
45.7000 1.9831 1.0000
45.7500 1.9586 1.0000
45.8000 0.9755 1.0000
45.8500 2.0004 1.0000
45.9000 1.9778 1.0000
45.9500 4.9880 1.0000
46.0000 2.0071 1.0000
46.0500 3.9747 1.0000
46.1000 3.9577 1.0000
46.1500 1.9670 1.0000
46.2000 2.0367 1.0000
46.2500 0.9873 1.0000
46.3000 1.9754 1.0000
46.3500 3.9346 1.0000
46.4000 4.0056 1.0000
46.4500 0.0000 1.0000
46.5000 0.9960 1.0000
46.5500 0.0000 1.0000
46.6000 0.9941 1.0000
46.6500 2.9923 1.0000
46.7000 0.9995 1.0000
46.7500 0.0000 1.0000
46.8000 0.9755 1.0000
46.8500 3.9925 1.0000
46.9000 1.9957 1.0000
46.9500 0.9762 1.0000
47.0000 0.0000 1.0000
47.0500 1.9828 1.0000
47.1000 0.9854 1.0000
47.1500 1.0085 1.0000
47.2000 0.9924 1.0000
47.2500 1.9949 1.0000
47.3000 4.0150 1.0000
47.3500 1.0309 1.0000
47.4000 0.9851 1.0000
47.4500 0.0000 1.0000
47.5000 0.0000 1.0000
47.5500 0.9824 1.0000
47.6000 1.9868 1.0000
47.6500 2.9920 1.0000
47.7000 0.0000 1.0000
47.7500 3.0294 1.0000
47.8000 0.0000 1.0000
47.8500 1.9690 1.0000
47.9000 1.9510 1.0000
47.9500 2.0277 1.0000
48.0000 0.9711 1.0000
48.0500 5.0279 1.0000
48.1000 1.0078 1.0000
48.1500 0.0000 1.0000
48.2000 0.9958 1.0000
48.2500 2.0067 1.0000
48.3000 2.9907 1.0000
48.3500 1.9937 1.0000
48.4000 0.0000 1.0000
48.4500 1.9775 1.0000
48.5000 1.9704 1.0000
48.5500 1.9799 1.0000
48.6000 3.0143 1.0000
48.6500 0.9736 1.0000
48.7000 3.9806 1.0000
48.7500 0.9893 1.0000
48.8000 3.9580 1.0000
48.8500 1.9930 1.0000
48.9000 1.9961 1.0000
48.9500 2.9520 1.0000
49.0000 0.9880 1.0000
49.0500 0.9976 1.0000
49.1000 3.0357 1.0000
49.1500 0.9967 1.0000
49.2000 1.9961 1.0000
49.2500 1.0019 1.0000
49.3000 4.9742 1.0000
49.3500 4.9445 1.0000
49.4000 1.0059 1.0000
49.4500 1.9745 1.0000
49.5000 3.9482 1.0000
49.5500 0.9966 1.0000
49.6000 3.9787 1.0000
49.6500 0.9658 1.0000
49.7000 2.0237 1.0000
49.7500 0.0000 1.0000
49.8000 2.0052 1.0000
49.8500 1.9869 1.0000
49.9000 1.9332 1.0000
49.9500 5.9909 1.0000
50.0000 0.9893 1.0000
50.0500 0.0000 1.0000
50.1000 0.0000 1.0000
50.1500 0.9932 1.0000
50.2000 2.0265 1.0000
50.2500 1.0019 1.0000
50.3000 5.0125 1.0000
50.3500 2.9749 1.0000
50.4000 1.0011 1.0000
50.4500 1.0186 1.0000
50.5000 1.9755 1.0000
50.5500 2.0162 1.0000
50.6000 4.9354 1.0000
50.6500 0.0000 1.0000
50.7000 1.9724 1.0000
50.7500 0.9945 1.0000
50.8000 1.0149 1.0000
50.8500 3.0396 1.0000
50.9000 1.9839 1.0000
50.9500 1.9637 1.0000
51.0000 0.0000 1.0000
51.0500 0.0000 1.0000
51.1000 1.9927 1.0000
51.1500 1.9984 1.0000
51.2000 0.0000 1.0000
51.2500 1.9785 1.0000
51.3000 0.0000 1.0000
51.3500 3.9737 1.0000
51.4000 1.9887 1.0000
51.4500 0.9736 1.0000
51.5000 1.9880 1.0000
51.5500 1.9544 1.0000
51.6000 1.9890 1.0000
51.6500 1.9951 1.0000
51.7000 1.9928 1.0000
51.7500 0.0000 1.0000
51.8000 2.9910 1.0000
51.8500 0.9954 1.0000
51.9000 1.9900 1.0000
51.9500 0.9825 1.0000
52.0000 0.0000 1.0000
52.0500 3.0099 1.0000
52.1000 3.9903 1.0000
52.1500 0.0000 1.0000
52.2000 3.9881 1.0000
52.2500 1.9981 1.0000
52.3000 6.9698 1.0000
52.3500 0.0000 1.0000
52.4000 0.9965 1.0000
52.4500 0.9871 1.0000
52.5000 0.0000 1.0000
52.5500 0.0000 1.0000
52.6000 2.9564 1.0000
52.6500 0.9955 1.0000
52.7000 1.9470 1.0000
52.7500 3.9434 1.0000
52.8000 1.9497 1.0000
52.8500 1.9915 1.0000
52.9000 0.0000 1.0000
52.9500 1.9981 1.0000
53.0000 6.9928 1.0000
53.0500 0.9955 1.0000
53.1000 0.9907 1.0000
53.1500 2.0071 1.0000
53.2000 5.9697 1.0000
53.2500 0.0000 1.0000
53.3000 2.0171 1.0000
53.3500 0.9847 1.0000
53.4000 0.9945 1.0000
53.4500 1.9947 1.0000
53.5000 4.9626 1.0000
53.5500 1.9644 1.0000
53.6000 3.0389 1.0000
53.6500 1.9907 1.0000
53.7000 1.0312 1.0000
53.7500 0.9955 1.0000
53.8000 0.9755 1.0000
53.8500 0.9949 1.0000
53.9000 1.9761 1.0000
53.9500 1.0026 1.0000
54.0000 0.9997 1.0000
54.0500 0.9953 1.0000
54.1000 3.0084 1.0000
54.1500 1.9754 1.0000
54.2000 3.9454 1.0000
54.2500 0.9956 1.0000
54.3000 3.9900 1.0000
54.3500 1.0226 1.0000
54.4000 1.0081 1.0000
54.4500 1.9900 1.0000
54.5000 0.9794 1.0000
54.5500 2.9677 1.0000
54.6000 1.9841 1.0000
54.6500 1.9761 1.0000
54.7000 2.0027 1.0000
54.7500 1.9993 1.0000
54.8000 2.0018 1.0000
54.8500 0.9873 1.0000
54.9000 0.0000 1.0000
54.9500 2.0059 1.0000
55.0000 1.0039 1.0000
55.0500 2.0010 1.0000
55.1000 0.0000 1.0000
55.1500 0.9794 1.0000
55.2000 0.0000 1.0000
55.2500 0.9919 1.0000
55.3000 2.9369 1.0000
55.3500 1.9664 1.0000
55.4000 1.9630 1.0000
55.4500 3.9281 1.0000
55.5000 2.9689 1.0000
55.5500 0.0000 1.0000
55.6000 1.0199 1.0000
55.6500 4.0025 1.0000
55.7000 0.0000 1.0000
55.7500 0.0000 1.0000
55.8000 0.9893 1.0000
55.8500 2.9649 1.0000
55.9000 1.9757 1.0000
55.9500 1.0062 1.0000
56.0000 3.9926 1.0000
56.0500 2.0053 1.0000
56.1000 1.9763 1.0000
56.1500 2.0091 1.0000
56.2000 2.9768 1.0000
56.2500 1.0166 1.0000
56.3000 1.9942 1.0000
56.3500 0.9990 1.0000
56.4000 1.9723 1.0000
56.4500 0.0000 1.0000
56.5000 1.9975 1.0000
56.5500 2.9889 1.0000
56.6000 0.9789 1.0000
56.6500 3.0051 1.0000
56.7000 3.0011 1.0000
56.7500 0.9942 1.0000
56.8000 2.9823 1.0000
56.8500 0.9950 1.0000
56.9000 3.9521 1.0000
56.9500 2.9816 1.0000
57.0000 3.0221 1.0000
57.0500 3.9934 1.0000
57.1000 0.9957 1.0000
57.1500 6.0067 1.0000
57.2000 3.0084 1.0000
57.2500 2.9966 1.0000
57.3000 1.9833 1.0000
57.3500 2.9741 1.0000
57.4000 5.9858 1.0000
57.4500 0.0000 1.0000
57.5000 4.0123 1.0000
57.5500 3.0060 1.0000
57.6000 3.9761 1.0000
57.6500 1.0032 1.0000
57.7000 0.9774 1.0000
57.7500 3.9617 1.0000
57.8000 0.9789 1.0000
57.8500 1.0115 1.0000
57.9000 0.9800 1.0000
57.9500 3.9732 1.0000
58.0000 0.0000 1.0000
58.0500 0.9755 1.0000
58.1000 2.9844 1.0000
58.1500 2.9910 1.0000
58.2000 0.9831 1.0000
58.2500 3.0090 1.0000
58.3000 2.9921 1.0000
58.3500 2.9639 1.0000
58.4000 0.0000 1.0000
58.4500 0.9839 1.0000
58.5000 5.9722 1.0000
58.5500 1.0286 1.0000
58.6000 1.9830 1.0000
58.6500 1.9999 1.0000
58.7000 1.9841 1.0000
58.7500 1.9708 1.0000
58.8000 1.0190 1.0000
58.8500 2.0058 1.0000
58.9000 4.9713 1.0000
58.9500 3.9580 1.0000
59.0000 1.0094 1.0000
59.0500 1.9967 1.0000
59.1000 1.9940 1.0000
59.1500 0.9966 1.0000
59.2000 1.9688 1.0000
59.2500 0.9814 1.0000
59.3000 1.9682 1.0000
59.3500 3.0229 1.0000
59.4000 0.0000 1.0000
59.4500 4.9802 1.0000
59.5000 1.0057 1.0000
59.5500 1.9849 1.0000
59.6000 2.0104 1.0000
59.6500 1.9692 1.0000
59.7000 3.0019 1.0000
59.7500 3.9591 1.0000
59.8000 1.9986 1.0000
59.8500 1.9651 1.0000
59.9000 0.9889 1.0000
59.9500 0.9658 1.0000
60.0000 3.9850 1.0000
60.0500 2.9709 1.0000
60.1000 1.9684 1.0000
60.1500 1.9797 1.0000
60.2000 0.9953 1.0000
60.2500 1.9773 1.0000
60.3000 4.0098 1.0000
60.3500 1.0020 1.0000
60.4000 3.9733 1.0000
60.4500 2.0140 1.0000
60.5000 2.1290 1.0000
60.5500 1.0019 1.0000
60.6000 1.9998 1.0000
60.6500 3.9771 1.0000
60.7000 2.0111 1.0000
60.7500 1.9987 1.0000
60.8000 2.0087 1.0000
60.8500 0.9865 1.0000
60.9000 0.0000 1.0000
60.9500 1.9812 1.0000
61.0000 0.0000 1.0000
61.0500 3.9913 1.0000
61.1000 1.9880 1.0000
61.1500 0.9934 1.0000
61.2000 0.0000 1.0000
61.2500 2.9541 1.0000
61.3000 2.9956 1.0000
61.3500 2.9519 1.0000
61.4000 2.9990 1.0000
61.4500 1.9795 1.0000
61.5000 1.9714 1.0000
61.5500 2.9699 1.0000
61.6000 1.0001 1.0000
61.6500 4.9433 1.0000
61.7000 3.0145 1.0000
61.7500 1.9934 1.0000
61.8000 1.0190 1.0000
61.8500 4.9721 1.0000
61.9000 2.0226 1.0000
61.9500 1.9517 1.0000
62.0000 0.0000 1.0000
62.0500 0.0000 1.0000
62.1000 0.0000 1.0000
62.1500 0.9835 1.0000
62.2000 4.9411 1.0000
62.2500 4.0140 1.0000
62.3000 3.9665 1.0000
62.3500 1.0045 1.0000
62.4000 4.1671 1.0000
62.4500 1.9902 1.0000
62.5000 1.0102 1.0000
62.5500 3.0078 1.0000
62.6000 3.0116 1.0000
62.6500 3.0422 1.0000
62.7000 5.0354 1.0000
62.7500 5.9589 1.0000
62.8000 2.9889 1.0000
62.8500 1.9711 1.0000
62.9000 3.0427 1.0000
62.9500 0.9840 1.0000
63.0000 3.9870 1.0000
63.0500 3.9857 1.0000
63.1000 3.9681 1.0000
63.1500 2.9729 1.0000
63.2000 3.0039 1.0000
63.2500 2.9638 1.0000
63.3000 3.9816 1.0000
63.3500 2.0063 1.0000
63.4000 3.0079 1.0000
63.4500 0.9861 1.0000
63.5000 1.9902 1.0000
63.5500 0.9894 1.0000
63.6000 1.9731 1.0000
63.6500 2.0055 1.0000
63.7000 2.9584 1.0000
63.7500 0.9890 1.0000
63.8000 0.9840 1.0000
63.8500 1.0015 1.0000
63.9000 3.9646 1.0000
63.9500 0.0000 1.0000
64.0000 3.9924 1.0000
64.0500 2.9937 1.0000
64.1000 4.9841 1.0000
64.1500 4.0250 1.0000
64.2000 3.0169 1.0000
64.2500 2.0183 1.0000
64.3000 2.9894 1.0000
64.3500 1.9783 1.0000
64.4000 3.0306 1.0000
64.4500 6.0287 1.0000
64.5000 2.0263 1.0000
64.5500 7.9654 1.0000
64.6000 8.0551 1.0000
64.6500 2.0009 1.0000
64.7000 3.9108 1.0000
64.7500 6.9526 1.0000
64.8000 3.0008 1.0000
64.8500 5.9734 1.0000
64.9000 2.9979 1.0000
64.9500 2.9591 1.0000
65.0000 2.0069 1.0000
65.0500 4.0096 1.0000
65.1000 5.9193 1.0000
65.1500 3.9865 1.0000
65.2000 3.0134 1.0000
65.2500 4.9431 1.0000
65.3000 4.9780 1.0000
65.3500 8.0381 1.0000
65.4000 10.0179 1.0000
65.4500 5.9259 1.0000
65.5000 5.9559 1.0000
65.5500 9.0997 1.0000
65.6000 14.9313 1.0000
65.6500 9.9702 1.0000
65.7000 14.8709 1.0000
65.7500 16.9606 1.0000
65.8000 18.9210 1.0000
65.8500 14.9425 1.0000
65.9000 29.8885 1.0000
65.9500 9.9965 1.0000
66.0000 30.0318 1.0000
66.0500 37.8984 1.0000
66.1000 53.9307 1.0000
66.1500 85.5321 1.0000
66.2000 840.4887 1.0000
66.2500 2783.0540 1.0000
66.3000 535.6694 1.0000
66.3500 437.3140 1.0000
66.4000 58.8377 1.0000
66.4500 26.9460 1.0000
66.5000 24.0228 1.0000
66.5500 18.8510 1.0000
66.6000 14.9257 1.0000
66.6500 9.8816 1.0000
66.7000 4.9759 1.0000
66.7500 11.0096 1.0000
66.8000 11.8907 1.0000
66.8500 8.9907 1.0000
66.9000 5.9865 1.0000
66.9500 5.9583 1.0000
67.0000 6.0368 1.0000
67.0500 10.0240 1.0000
67.1000 3.9904 1.0000
67.1500 5.9267 1.0000
67.2000 5.9355 1.0000
67.2500 6.9119 1.0000
67.3000 1.0149 1.0000
67.3500 7.9193 1.0000
67.4000 3.9510 1.0000
67.4500 6.0057 1.0000
67.5000 5.9798 1.0000
67.5500 2.9929 1.0000
67.6000 9.0490 1.0000
67.6500 8.9075 1.0000
67.7000 2.9947 1.0000
67.7500 7.0369 1.0000
67.8000 5.9786 1.0000
67.8500 4.9904 1.0000
67.9000 3.9217 1.0000
67.9500 5.9958 1.0000
68.0000 2.1465 1.0000
68.0500 3.9732 1.0000
68.1000 5.9701 1.0000
68.1500 7.9392 1.0000
68.2000 4.9425 1.0000
68.2500 6.9548 1.0000
68.3000 2.9314 1.0000
68.3500 4.9717 1.0000
68.4000 2.9766 1.0000
68.4500 5.9789 1.0000
68.5000 1.9602 1.0000
68.5500 3.9675 1.0000
68.6000 4.0124 1.0000
68.6500 1.9743 1.0000
68.7000 2.9446 1.0000
68.7500 2.9880 1.0000
68.8000 1.0039 1.0000
68.8500 2.0062 1.0000
68.9000 1.9984 1.0000
68.9500 2.9582 1.0000
69.0000 6.0268 1.0000
69.0500 5.0102 1.0000
69.1000 5.0102 1.0000
69.1500 4.0105 1.0000
69.2000 3.9755 1.0000
69.2500 9.9602 1.0000
69.3000 4.9869 1.0000
69.3500 0.0000 1.0000
69.4000 5.9921 1.0000
69.4500 4.9963 1.0000
69.5000 2.9982 1.0000
69.5500 2.9942 1.0000
69.6000 1.9996 1.0000
69.6500 1.9693 1.0000
69.7000 2.9420 1.0000
69.7500 3.0043 1.0000
69.8000 0.9531 1.0000
69.8500 2.0024 1.0000
69.9000 3.0476 1.0000
69.9500 3.0101 1.0000
70.0000 3.9572 1.0000
70.0500 1.9900 1.0000
70.1000 0.9794 1.0000
70.1500 4.0154 1.0000
70.2000 2.9928 1.0000
70.2500 0.9997 1.0000
70.3000 5.0309 1.0000
70.3500 3.9860 1.0000
70.4000 2.0398 1.0000
70.4500 3.0365 1.0000
70.5000 0.0000 1.0000
70.5500 4.9470 1.0000
70.6000 1.9987 1.0000
70.6500 2.1670 1.0000
70.7000 2.9966 1.0000
70.7500 0.9807 1.0000
70.8000 5.0083 1.0000
70.8500 2.9810 1.0000
70.9000 3.0975 1.0000
70.9500 6.9870 1.0000
71.0000 6.9125 1.0000
71.0500 2.9879 1.0000
71.1000 2.0034 1.0000
71.1500 1.9682 1.0000
71.2000 4.9089 1.0000
71.2500 1.9768 1.0000
71.3000 0.9629 1.0000
71.3500 3.0344 1.0000
71.4000 0.9918 1.0000
71.4500 2.9735 1.0000
71.5000 5.9603 1.0000
71.5500 2.9705 1.0000
71.6000 3.9675 1.0000
71.6500 0.0000 1.0000
71.7000 0.0000 1.0000
71.7500 5.9588 1.0000
71.8000 0.9854 1.0000
71.8500 3.9814 1.0000
71.9000 0.9905 1.0000
71.9500 3.9869 1.0000
72.0000 3.9818 1.0000
72.0500 2.9966 1.0000
72.1000 1.0019 1.0000
72.1500 1.9888 1.0000
72.2000 0.9934 1.0000
72.2500 2.0149 1.0000
72.3000 2.9814 1.0000
72.3500 4.9201 1.0000
72.4000 2.9434 1.0000
72.4500 0.0000 1.0000
72.5000 2.9576 1.0000
72.5500 2.9966 1.0000
72.6000 2.9706 1.0000
72.6500 0.0000 1.0000
72.7000 3.0384 1.0000
72.7500 1.0250 1.0000
72.8000 0.0000 1.0000
72.8500 3.0055 1.0000
72.9000 6.9730 1.0000
72.9500 2.0029 1.0000
73.0000 3.9517 1.0000
73.0500 2.0002 1.0000
73.1000 2.0167 1.0000
73.1500 2.9971 1.0000
73.2000 2.0017 1.0000
73.2500 0.9936 1.0000
73.3000 4.9280 1.0000
73.3500 2.9844 1.0000
73.4000 2.9678 1.0000
73.4500 0.0000 1.0000
73.5000 1.0053 1.0000
73.5500 1.9858 1.0000
73.6000 3.9936 1.0000
73.6500 4.0043 1.0000
73.7000 1.9928 1.0000
73.7500 0.9990 1.0000
73.8000 1.0237 1.0000
73.8500 1.0080 1.0000
73.9000 2.9789 1.0000
73.9500 1.9562 1.0000
74.0000 2.0297 1.0000
74.0500 2.9842 1.0000
74.1000 1.0200 1.0000
74.1500 2.9757 1.0000
74.2000 0.0000 1.0000
74.2500 1.9916 1.0000
74.3000 1.9895 1.0000
74.3500 0.0000 1.0000
74.4000 3.9227 1.0000
74.4500 3.9414 1.0000
74.5000 1.9812 1.0000
74.5500 5.0626 1.0000
74.6000 0.0000 1.0000
74.6500 2.9871 1.0000
74.7000 0.9977 1.0000
74.7500 1.9816 1.0000
74.8000 4.0071 1.0000
74.8500 1.9533 1.0000
74.9000 1.9759 1.0000
74.9500 0.0000 1.0000
75.0000 1.9751 1.0000
75.0500 1.0237 1.0000
75.1000 0.0000 1.0000
75.1500 4.0402 1.0000
75.2000 0.9978 1.0000
75.2500 0.0000 1.0000
75.3000 0.9924 1.0000
75.3500 2.0343 1.0000
75.4000 2.9674 1.0000
75.4500 1.9963 1.0000
75.5000 4.9766 1.0000
75.5500 2.9470 1.0000
75.6000 3.0135 1.0000
75.6500 2.0028 1.0000
75.7000 0.9887 1.0000
75.7500 3.9484 1.0000
75.8000 0.0000 1.0000
75.8500 1.9879 1.0000
75.9000 4.0370 1.0000
75.9500 3.9821 1.0000
76.0000 2.0220 1.0000
76.0500 1.0034 1.0000
76.1000 0.0000 1.0000
76.1500 1.9963 1.0000
76.2000 0.9972 1.0000
76.2500 2.9858 1.0000
76.3000 1.0115 1.0000
76.3500 4.0047 1.0000
76.4000 2.9728 1.0000
76.4500 3.9760 1.0000
76.5000 2.0016 1.0000
76.5500 2.9663 1.0000
76.6000 2.9868 1.0000
76.6500 1.9857 1.0000
76.7000 4.0131 1.0000
76.7500 2.9715 1.0000
76.8000 2.9591 1.0000
76.8500 0.9892 1.0000
76.9000 1.0039 1.0000
76.9500 0.9941 1.0000
77.0000 2.9828 1.0000
77.0500 0.0000 1.0000
77.1000 3.0147 1.0000
77.1500 2.9786 1.0000
77.2000 3.9572 1.0000
77.2500 3.9595 1.0000
77.3000 2.9406 1.0000
77.3500 0.0000 1.0000
77.4000 0.9899 1.0000
77.4500 1.9595 1.0000
77.5000 3.9736 1.0000
77.5500 1.0014 1.0000
77.6000 5.9818 1.0000
77.6500 0.0000 1.0000
77.7000 1.9910 1.0000
77.7500 3.9320 1.0000
77.8000 1.0123 1.0000
77.8500 1.9942 1.0000
77.9000 0.0000 1.0000
77.9500 4.9681 1.0000
78.0000 3.9983 1.0000
78.0500 4.9128 1.0000
78.1000 1.0122 1.0000
78.1500 3.9800 1.0000
78.2000 1.0109 1.0000
78.2500 1.0007 1.0000
78.3000 1.9665 1.0000
78.3500 2.0164 1.0000
78.4000 1.0166 1.0000
78.4500 1.0121 1.0000
78.5000 2.9980 1.0000
78.5500 0.0000 1.0000
78.6000 1.9979 1.0000
78.6500 2.9664 1.0000
78.7000 2.0120 1.0000
78.7500 2.9896 1.0000
78.8000 2.0059 1.0000
78.8500 0.9792 1.0000
78.9000 1.0014 1.0000
78.9500 3.0047 1.0000
79.0000 1.9892 1.0000
79.0500 1.9827 1.0000
79.1000 0.9847 1.0000
79.1500 0.0000 1.0000
79.2000 0.0000 1.0000
79.2500 6.9765 1.0000
79.3000 2.9777 1.0000
79.3500 0.0000 1.0000
79.4000 6.8994 1.0000
79.4500 1.1427 1.0000
79.5000 0.9893 1.0000
79.5500 1.0025 1.0000
79.6000 3.0275 1.0000
79.6500 1.0294 1.0000
79.7000 2.9982 1.0000
79.7500 0.9990 1.0000
79.8000 0.9848 1.0000
79.8500 3.9884 1.0000
79.9000 2.9889 1.0000
79.9500 1.9753 1.0000
80.0000 0.0000 1.0000
80.0500 0.9893 1.0000
80.1000 2.9581 1.0000
80.1500 1.0025 1.0000
80.2000 0.9988 1.0000
80.2500 3.0224 1.0000
80.3000 0.9997 1.0000
80.3500 1.0013 1.0000
80.4000 0.0000 1.0000
80.4500 0.0000 1.0000
80.5000 1.9725 1.0000
80.5500 1.0411 1.0000
80.6000 1.9923 1.0000
80.6500 1.9945 1.0000
80.7000 2.9645 1.0000
80.7500 0.9741 1.0000
80.8000 2.9887 1.0000
80.8500 0.9902 1.0000
80.9000 1.9852 1.0000
80.9500 2.9431 1.0000
81.0000 1.9878 1.0000
81.0500 1.0264 1.0000
81.1000 1.9736 1.0000
81.1500 2.9925 1.0000
81.2000 2.9999 1.0000
81.2500 0.0000 1.0000
81.3000 1.9689 1.0000
81.3500 3.9742 1.0000
81.4000 1.9606 1.0000
81.4500 4.0331 1.0000
81.5000 1.9813 1.0000
81.5500 1.0056 1.0000
81.6000 0.0000 1.0000
81.6500 2.0066 1.0000
81.7000 0.9960 1.0000
81.7500 2.9860 1.0000
81.8000 2.9952 1.0000
81.8500 3.9574 1.0000
81.9000 1.9677 1.0000
81.9500 0.9890 1.0000
82.0000 6.9069 1.0000
82.0500 2.9766 1.0000
82.1000 4.9611 1.0000
82.1500 1.9680 1.0000
82.2000 1.0309 1.0000
82.2500 2.9418 1.0000
82.3000 0.9994 1.0000
82.3500 3.0141 1.0000
82.4000 0.9802 1.0000
82.4500 2.9678 1.0000
82.5000 1.0172 1.0000
82.5500 0.9940 1.0000
82.6000 0.0000 1.0000
82.6500 2.0103 1.0000
82.7000 1.9939 1.0000
82.7500 3.9767 1.0000
82.8000 2.0112 1.0000
82.8500 0.0000 1.0000
82.9000 1.9679 1.0000
82.9500 3.0111 1.0000
83.0000 2.0094 1.0000
83.0500 0.0000 1.0000
83.1000 1.0026 1.0000
83.1500 1.9471 1.0000
83.2000 0.0000 1.0000
83.2500 0.9791 1.0000
83.3000 0.9907 1.0000
83.3500 2.9770 1.0000
83.4000 4.0093 1.0000
83.4500 0.9893 1.0000
83.5000 1.9962 1.0000
83.5500 2.9788 1.0000
83.6000 1.9811 1.0000
83.6500 0.9930 1.0000
83.7000 1.9423 1.0000
83.7500 0.9998 1.0000
83.8000 1.9876 1.0000
83.8500 4.0082 1.0000
83.9000 1.9998 1.0000
83.9500 0.9918 1.0000
84.0000 0.0000 1.0000
84.0500 0.9935 1.0000
84.1000 7.9373 1.0000
84.1500 0.9835 1.0000
84.2000 2.0078 1.0000
84.2500 0.9983 1.0000
84.3000 2.0246 1.0000
84.3500 0.9948 1.0000
84.4000 2.0097 1.0000
84.4500 1.0001 1.0000
84.5000 4.9912 1.0000
84.5500 0.9755 1.0000
84.6000 2.0272 1.0000
84.6500 1.0063 1.0000
84.7000 0.0000 1.0000
84.7500 5.0273 1.0000
84.8000 1.9630 1.0000
84.8500 1.9937 1.0000
84.9000 0.0000 1.0000
84.9500 1.9852 1.0000
85.0000 1.9611 1.0000
85.0500 2.0080 1.0000
85.1000 0.9831 1.0000
85.1500 4.9972 1.0000
85.2000 0.9995 1.0000
85.2500 3.9831 1.0000
85.3000 1.9801 1.0000
85.3500 3.9567 1.0000
85.4000 2.0157 1.0000
85.4500 4.9786 1.0000
85.5000 0.9755 1.0000
85.5500 0.0000 1.0000
85.6000 3.0103 1.0000
85.6500 4.9668 1.0000
85.7000 0.0000 1.0000
85.7500 0.9839 1.0000
85.8000 0.9736 1.0000
85.8500 0.0000 1.0000
85.9000 0.9945 1.0000
85.9500 3.0174 1.0000
86.0000 1.0286 1.0000
86.0500 1.9840 1.0000
86.1000 0.0000 1.0000
86.1500 1.9749 1.0000
86.2000 1.0060 1.0000
86.2500 3.9761 1.0000
86.3000 3.0247 1.0000
86.3500 0.9783 1.0000
86.4000 1.9868 1.0000
86.4500 0.0000 1.0000
86.5000 1.0101 1.0000
86.5500 2.9508 1.0000
86.6000 1.9870 1.0000
86.6500 1.0010 1.0000
86.7000 2.9915 1.0000
86.7500 4.9603 1.0000
86.8000 3.0194 1.0000
86.8500 5.0446 1.0000
86.9000 2.9579 1.0000
86.9500 0.0000 1.0000
87.0000 0.9825 1.0000
87.0500 0.0000 1.0000
87.1000 2.0049 1.0000
87.1500 2.9712 1.0000
87.2000 3.0008 1.0000
87.2500 0.0000 1.0000
87.3000 1.0071 1.0000
87.3500 2.9658 1.0000
87.4000 3.0534 1.0000
87.4500 2.0585 1.0000
87.5000 1.9874 1.0000
87.5500 5.0527 1.0000
87.6000 0.9928 1.0000
87.6500 0.9899 1.0000
87.7000 1.9842 1.0000
87.7500 3.0047 1.0000
87.8000 2.9840 1.0000
87.8500 0.9820 1.0000
87.9000 0.9950 1.0000
87.9500 0.9811 1.0000
88.0000 1.9412 1.0000
88.0500 1.9623 1.0000
88.1000 2.9445 1.0000
88.1500 0.9975 1.0000
88.2000 0.9629 1.0000
88.2500 0.9993 1.0000
88.3000 4.9958 1.0000
88.3500 4.0305 1.0000
88.4000 1.0312 1.0000
88.4500 1.9610 1.0000
88.5000 2.9426 1.0000
88.5500 0.0000 1.0000
88.6000 2.9805 1.0000
88.6500 1.0002 1.0000
88.7000 4.9263 1.0000
88.7500 1.9823 1.0000
88.8000 2.9959 1.0000
88.8500 2.9615 1.0000
88.9000 0.0000 1.0000
88.9500 3.9898 1.0000
89.0000 0.9889 1.0000
89.0500 0.9767 1.0000
89.1000 0.9691 1.0000
89.1500 2.9843 1.0000
89.2000 5.0315 1.0000
89.2500 0.9827 1.0000
89.3000 0.9794 1.0000
89.3500 1.0048 1.0000
89.4000 2.0412 1.0000
89.4500 0.9802 1.0000
89.5000 0.9966 1.0000
89.5500 4.9420 1.0000
89.6000 0.0000 1.0000
89.6500 2.9676 1.0000
89.7000 0.0000 1.0000
89.7500 0.0000 1.0000
89.8000 3.9660 1.0000
89.8500 0.0000 1.0000
89.9000 4.0326 1.0000
89.9500 0.9892 1.0000
90.0000 2.9491 1.0000
*RAS_INT_END
*RAS_DATA_END